Workbook

Sheet sheet1
A1: EASYNETT INT'L COLLEGE OF TECH. (EICT)
A3: 76, WILMER CRESCENT, OLODI-APAPA, LAGOS
A4: SESSION | C4: 2025/2026
B5: FIRST TERM | C5: BROADSHEET | AO5: CUMMULATIVE SCORE
A7: S/NO | B7: JSS 1A | C7: AGRICULTURAL SCIENCE | E7: BASIC SCIENCE | G7: BASIC TECH | I7: BUSINESS STUDIES | K7: CULTURAL & CREATIVE ART | L7: 10 | M7: CIVIC EDUCATION | N7: 12 | O7: CHRISTIAN RELIGIOUS STUDIES | Q7: ENGLISH LANGUAGE | S7: ENGLISH PHONETICS | U7: FRENCH | W7: HISTORY | Y7: HOME ECONOMICS | AA7: IGBO LANGUAGE | AC7: INFORMATION TECHNOLOGY | AE7: MATHEMATICS | AG7: PHYSICAL & HEALTH EDUCATION | AI7: SECURITY EDUCATION | AK7: SOCIAL STUDIES | AM7: YORUBA LANGUAGE | AO7: TOTAL | AP7: AVERAGE
B8: STUDENT NAME | C8: CA | D8: EXAM | E8: CA | F8: EXAM | G8: CA | H8: EXAM | I8: CA | J8: EXAM | K8: CA | L8: EXAM | M8: CA | N8: EXAM | O8: CA | P8: EXAM | Q8: CA | R8: EXAM | S8: CA | T8: EXAM | U8: CA | V8: EXAM | W8: CA | X8: EXAM | Y8: CA | Z8: EXAM | AA8: CA | AB8: EXAM | AC8: CA | AD8: EXAM | AE8: CA | AF8: EXAM | AG8: CA | AH8: EXAM | AI8: CA | AJ8: EXAM | AK8: CA | AL8: EXAM | AM8: CA | AN8: EXAM
A9: 1 | B9: ADAKARAZA SAMUEL | C9: 28 | D9: 28 | E9: 28 | F9: 28 | G9: 17 | H9: 8 | I9: 17 | J9: 15 | K9: 13 | L9: 20 | M9: 17 | N9: 10 | O9: 21 | P9: 30 | Q9: 13 | R9: 11 | U9: 17 | V9: 6 | W9: 15 | X9: 11 | Y9: 20 | Z9: 24 | AC9: 18 | AD9: 10 | AE9: 20 | AF9: 20 | AG9: 29 | AH9: 10 | AI9: 15 | AJ9: 3 | AK9: 15 | AL9: 16 | AM9: 21 | AN9: 22 | AO9: =SUM(C9:AN9) -> 596 | AP9: =AO9/17 -> 35.058824
A10: 2 | B10: ADEOLA PEDRO | C10: 28 | D10: 39 | E10: 25 | F10: 39 | G10: 20 | H10: 22 | I10: 24 | J10: 23 | K10: 21 | L10: 20 | M10: 24 | N10: 10 | O10: 20 | P10: 30 | Q10: 24 | R10: 25 | U10: 22 | V10: 37 | W10: 28 | X10: 36 | Y10: 25 | Z10: 30 | AC10: 24 | AD10: 29 | AE10: 20 | AF10: 20 | AG10: 29 | AH10: 28 | AI10: 17 | AJ10: 4 | AK10: 14 | AL10: 22 | AM10: 27 | AN10: 40 | AO10: =SUM(C10:AN10) -> 846 | AP10: =AO10/17 -> 49.764706
A11: 3 | B11: ASAMS DANIELLA | C11: 28 | D11: 35 | E11: 25 | F11: 55 | G11: 22 | H11: 60 | I11: 18 | J11: 22 | K11: 20 | L11: 20 | M11: 17 | N11: 38 | O11: 28 | P11: 45 | Q11: 23 | R11: 52 | U11: 20 | V11: 43 | W11: 26 | X11: 35 | Y11: 25 | Z11: 31 | AC11: 18 | AD11: 37 | AE11: 20 | AF11: 30 | AG11: 26 | AH11: 32 | AI11: 20 | AJ11: 25 | AK11: 20 | AL11: 31 | AM11: 26 | AN11: 40 | AO11: =SUM(C11:AN11) -> 1013 | AP11: =AO11/17 -> 59.588235
A12: 4 | B12: ASIBOR NANCY | C12: 28 | D12: 50 | E12: 27 | F12: 51 | G12: 20 | H12: 30 | I12: 24 | J12: 30 | K12: 29 | L12: 38 | M12: 23 | N12: 53 | O12: 23 | P12: 36 | Q12: 27 | R12: 26 | U12: 10 | V12: 44 | W12: 27 | X12: 35 | Y12: 23 | Z12: 30 | AC12: 21 | AD12: 36 | AE12: 20 | AF12: 28 | AG12: 26 | AH12: 40 | AI12: 17 | AJ12: 27 | AK12: 20 | AL12: 41 | AM12: 19 | AN12: 26 | AO12: =SUM(C12:AN12) -> 1005 | AP12: =AO12/17 -> 59.117647
A13: 5 | B13: BANKOLE AMEERAT | C13: 28 | D13: 68 | E13: 28 | F13: 66 | G13: 22 | H13: 52 | I13: 16 | J13: 20 | K13: 20 | L13: 35 | M13: 22 | N13: 33 | O13: 24 | P13: 55 | Q13: 24 | R13: 41 | U13: 22 | V13: 56 | W13: 29 | X13: 57 | Y13: 27 | Z13: 53 | AC13: 24 | AD13: 39 | AE13: 25 | AF13: 40 | AG13: 26 | AH13: 37 | AI13: 21 | AJ13: 33 | AK13: 22 | AL13: 53 | AM13: 23 | AN13: 68 | AO13: =SUM(C13:AN13) -> 1209 | AP13: =AO13/17 -> 71.117647
A14: 6 | B14: CHIEKEZIE MAXWELL | C14: 28 | D14: 18 | E14: 22 | F14: 21 | G14: 20 | H14: 5 | I14: 16 | J14: 32 | K14: 20 | L14: 20 | M14: 14 | N14: 22 | O14: 17 | P14: 13 | Q14: 18 | R14: 14 | U14: 18 | V14: 1 | W14: 17 | X14: 24 | Y14: 20 | Z14: 20 | AC14: 18 | AD14: 25 | AE14: 20 | AF14: 18 | AG14: 29 | AH14: 7 | AI14: 14 | AJ14: 5 | AK14: 20 | AL14: 17 | AM14: 12 | AN14: 7 | AO14: =SUM(C14:AN14) -> 592 | AP14: =AO14/17 -> 34.823529
A15: 7 | B15: EDET MOSES | C15: 28 | D15: 30 | E15: 25 | F15: 37 | G15: 25 | H15: 42 | I15: 14 | J15: 42 | K15: 27 | L15: 40 | M15: 20 | N15: 22 | O15: 18 | P15: 45 | Q15: 19 | R15: 18 | U15: 11 | V15: 41 | W15: 23 | X15: 41 | Y15: 27 | Z15: 43 | AC15: 17 | AD15: 34 | AE15: 20 | AF15: 48 | AG15: 27 | AH15: 28 | AI15: 15 | AJ15: 38 | AK15: 15 | AL15: 18 | AM15: 22 | AN15: 16 | AO15: =SUM(C15:AN15) -> 936 | AP15: =AO15/17 -> 55.058824
A16: 8 | B16: ENEJOH PHINEHAS | C16: 28 | D16: 39 | E16: 22 | F16: 24 | G16: 28 | H16: 4 | I16: 15 | J16: 15 | K16: 20 | L16: 20 | M16: 21 | N16: 26 | O16: 18 | P16: 16 | Q16: 18 | R16: 13 | U16: 19 | V16: 8 | W16: 23 | X16: 9 | Y16: 20 | Z16: 20 | AC16: 18 | AD16: 22 | AE16: 20 | AF16: 14 | AG16: 29 | AH16: 20 | AI16: 18 | AJ16: 14 | AK16: 23 | AL16: 25 | AM16: 13 | AN16: 27 | AO16: =SUM(C16:AN16) -> 669 | AP16: =AO16/17 -> 39.352941
A17: 9 | B17: EWELUKWA FAVOUR | C17: 28 | D17: 63 | E17: 27 | F17: 53 | G17: 27 | H17: 46 | I17: 20 | J17: 40 | K17: 26 | L17: 30 | M17: 17 | N17: 16 | O17: 21 | P17: 49 | Q17: 28 | R17: 40 | U17: 20 | V17: 50 | W17: 30 | X17: 54 | Y17: 29 | Z17: 53 | AC17: 23 | AD17: 38 | AE17: 20 | AF17: 25 | AG17: 26 | AH17: 35 | AI17: 19 | AJ17: 24 | AK17: 23 | AL17: 35 | AM17: 24 | AN17: 14 | AO17: =SUM(C17:AN17) -> 1073 | AP17: =AO17/17 -> 63.117647
A18: 10 | B18: HAMMED OLAMIDE | C18: 28 | D18: 5 | E18: 17 | F18: 5 | G18: 26 | H18: 5 | I18: 14 | J18: 15 | K18: 10 | L18: 20 | M18: 14 | N18: 10 | O18: 18 | P18: 16 | Q18: 17 | R18: 9 | U18: 15 | V18: 2 | W18: 17 | X18: 1 | Y18: 20 | Z18: 20 | AC18: 11 | AD18: 2 | AE18: 15 | AF18: 5 | AG18: 30 | AH18: 1 | AI18: 12 | AJ18: 5 | AK18: 8 | AL18: 9 | AM18: 9 | AN18: 1 | AO18: =SUM(C18:AN18) -> 412 | AP18: =AO18/17 -> 24.235294
A19: 11 | B19: HAMZAT AKOREDE | C19: 28 | D19: 27 | E19: 18 | F19: 2 | G19: 25 | H19: 18 | I19: 14 | J19: 15 | K19: 20 | L19: 20 | M19: 18 | N19: 10 | O19: 18 | P19: 11 | Q19: 18 | R19: 15 | U19: 17 | V19: 7 | W19: 22 | X19: 15 | Y19: 20 | Z19: 25 | AC19: 14 | AD19: 12 | AE19: 18 | AF19: 5 | AG19: 30 | AH19: 7 | AI19: 15 | AJ19: 5 | AK19: 20 | AL19: 15 | AM19: 19 | AN19: 27 | AO19: =SUM(C19:AN19) -> 570 | AP19: =AO19/17 -> 33.529412
A20: 12 | B20: JAMES DIVINE | C20: 28 | D20: 28 | E20: 19 | F20: 14 | G20: 27 | H20: 7 | I20: 16 | J20: 24 | K20: 20 | L20: 20 | M20: 19 | N20: 12 | O20: 18 | P20: 24 | Q20: 21 | R20: 10 | U20: 16 | V20: 4 | W20: 21 | X20: 13 | Y20: 25 | Z20: 25 | AC20: 14 | AD20: 23 | AE20: 18 | AF20: 18 | AG20: 30 | AH20: 10 | AI20: 16 | AJ20: 7 | AK20: 22 | AL20: 23 | AM20: 14 | AN20: 38 | AO20: =SUM(C20:AN20) -> 644 | AP20: =AO20/17 -> 37.882353
... A30: 22 | B30: WASIU NIMOTALLAH | C30: 28 | D30: 28 | E30: 28 | F30: 28 | G30: 28 | H30: 43 | I30: 17 | J30: 16 | K30: 24 | L30: 30 | M30: 17 | N30: 29 | O30: 21 | P30: 20 | Q30: 21 | R30: 15 | U30: 30 | V30: 38 | W30: 23 | X30: 27 | Y30: 20 | Z30: 20 | AC30: 17 | AD30: 22 | AE30: 21 | AF30: 40 | AG30: 26 | AH30: 20 | AI30: 21 | AJ30: 8 | AK30: 19 | AL30: 14 | AM30: 21 | AN30: 60 | AO30: =SUM(C30:AN30) -> 840 | AP30: =AO30/17 -> 49.411765
A31: 23 | AO31: =SUM(C31:AN31) -> 0 | AP31: =AO31/17 -> 0
A32: 24 | AO32: =SUM(C32:AN32) -> 0 | AP32: =AO32/17 -> 0
A33: 25 | AO33: =SUM(C33:AN33) -> 0 | AP33: =AO33/17 -> 0
A34: 26 | AO34: =SUM(C34:AN34) -> 0 | AP34: =AO34/17 -> 0
A35: 27 | AO35: =SUM(C35:AN35) -> 0 | AP35: =AO35/17 -> 0
A36: 28 | AO36: =SUM(C36:AN36) -> 0 | AP36: =AO36/17 -> 0
A37: 29 | AO37: =SUM(C37:AN37) -> 0 | AP37: =AO37/17 -> 0
A38: 30 | AO38: =SUM(C38:AN38) -> 0 | AP38: =AO38/17 -> 0
A39: 31 | AO39: =SUM(C39:AN39) -> 0 | AP39: =AO39/17 -> 0
A40: 32 | AO40: =SUM(C40:AN40) -> 0 | AP40: =AO40/17 -> 0
A41: 33 | AO41: =SUM(C41:AN41) -> 0 | AP41: =AO41/17 -> 0
A42: 34 | AO42: =SUM(C42:AN42) -> 0 | AP42: =AO42/17 -> 0
... A48: 40 | AO48: =SUM(C48:AN48) -> 0 | AP48: =AO48/17 -> 0

Sheet sheet2
A1: EASYNETT INT'L COLLEGE OF TECH. (EICT)
A3: 76, WILMER CRESCENT, OLODI-APAPA, LAGOS
A4: SESSION | C4: 2025/2026
B5: FIRST TERM | C5: NO OF TIMES SCHOOL OPENED | D5: NUMBER IN CLASS | E5: NEXT TERM BEGINS | G5: ADDITIONAL DETAILS
C6: 128 | D6: 22 | E6: 12TH JANUARY 2026
A7: S/NO | B7: STUDENT NAME | C7: NO OF TIMES PRESENT | D7: CLASS AVERAGE | E7: POSITION | F7: CLASS TEACHER'S REMARK | G7: PRINCIPAL'S COMMENT | H7: PUNCTUALITY | I7: NEATNESS | J7: HONESTY | K7: CREATIVITY
A8: 1 | B8: =(sheet1!B9) -> ADAKARAZA SAMUEL | C8: 118 | D8: =(sheet1!AP9) -> 35.058824 | E8: =RANK(D8,$D$8:$D$29)&IF(OR(RANK(D8,$D$8:$D$29)=11,RANK(D8,$D$8:$D$29)=12,RANK(D8,$D$8:$D$29)=13),"th",CHOOSE(MIN(5,MOD(RANK(D8,$D$8:$D$29),10)+1),"th","st","nd","rd","th")) -> 19th | F8: He is well behaved and obedient | G8: A good result, you still need to work harder on your present scores. | H8: A | I8: A | J8: A | K8: A
A9: 2 | B9: =(sheet1!B10) -> ADEOLA PEDRO | C9: 128 | D9: =(sheet1!AP10) -> 49.764706 | E9: =RANK(D9,$D$8:$D$29)&IF(OR(RANK(D9,$D$8:$D$29)=11,RANK(D9,$D$8:$D$29)=12,RANK(D9,$D$8:$D$29)=13),"th",CHOOSE(MIN(5,MOD(RANK(D9,$D$8:$D$29),10)+1),"th","st","nd","rd","th")) -> 12th | F9: He is always gentle and sociable | G9: Fairly good. Give greater attention to your study next term | H9: B | I9: B | J9: B | K9: B
A10: 3 | B10: =(sheet1!B11) -> ASAMS DANIELLA | C10: 126 | D10: =(sheet1!AP11) -> 59.588235 | E10: =RANK(D10,$D$8:$D$29)&IF(OR(RANK(D10,$D$8:$D$29)=11,RANK(D10,$D$8:$D$29)=12,RANK(D10,$D$8:$D$29)=13),"th",CHOOSE(MIN(5,MOD(RANK(D10,$D$8:$D$29),10)+1),"th","st","nd","rd","th")) -> 7th | F10: She is always neat and punctual to school | G10: This is good result. Keep working hard | H10: C | I10: C | J10: C | K10: C
A11: 4 | B11: =(sheet1!B12) -> ASIBOR NANCY | C11: 108 | D11: =(sheet1!AP12) -> 59.117647 | E11: =RANK(D11,$D$8:$D$29)&IF(OR(RANK(D11,$D$8:$D$29)=11,RANK(D11,$D$8:$D$29)=12,RANK(D11,$D$8:$D$29)=13),"th",CHOOSE(MIN(5,MOD(RANK(D11,$D$8:$D$29),10)+1),"th","st","nd","rd","th")) -> 8th | F11: She is gentle and neat | G11: This performance is satisfactory. | H11: D | I11: D | J11: D | K11: D
A12: 5 | B12: =(sheet1!B13) -> BANKOLE AMEERAT | C12: 128 | D12: =(sheet1!AP13) -> 71.117647 | E12: =RANK(D12,$D$8:$D$29)&IF(OR(RANK(D12,$D$8:$D$29)=11,RANK(D12,$D$8:$D$29)=12,RANK(D12,$D$8:$D$29)=13),"th",CHOOSE(MIN(5,MOD(RANK(D12,$D$8:$D$29),10)+1),"th","st","nd","rd","th")) -> 1st | F12: He is an obedient student | G12: Good performance. Keep it up | H12: E | I12: E | J12: E | K12: E
A13: 6 | B13: =(sheet1!B14) -> CHIEKEZIE MAXWELL | C13: 116 | D13: =(sheet1!AP14) -> 34.823529 | E13: =RANK(D13,$D$8:$D$29)&IF(OR(RANK(D13,$D$8:$D$29)=11,RANK(D13,$D$8:$D$29)=12,RANK(D13,$D$8:$D$29)=13),"th",CHOOSE(MIN(5,MOD(RANK(D13,$D$8:$D$29),10)+1),"th","st","nd","rd","th")) -> 20th | F13: He is respectful and always neat | G13: Fair result. You can improve in your weak subjects
A14: 7 | B14: =(sheet1!B15) -> EDET MOSES | C14: 112 | D14: =(sheet1!AP15) -> 55.058824 | E14: =RANK(D14,$D$8:$D$29)&IF(OR(RANK(D14,$D$8:$D$29)=11,RANK(D14,$D$8:$D$29)=12,RANK(D14,$D$8:$D$29)=13),"th",CHOOSE(MIN(5,MOD(RANK(D14,$D$8:$D$29),10)+1),"th","st","nd","rd","th")) -> 9th | F14: He is always neat and obedient | G14: Fairly good result. You need to work extra hard in your weak subjects area
A15: 8 | B15: =(sheet1!B16) -> ENEJOH PHINEHAS | C15: 120 | D15: =(sheet1!AP16) -> 39.352941 | E15: =RANK(D15,$D$8:$D$29)&IF(OR(RANK(D15,$D$8:$D$29)=11,RANK(D15,$D$8:$D$29)=12,RANK(D15,$D$8:$D$29)=13),"th",CHOOSE(MIN(5,MOD(RANK(D15,$D$8:$D$29),10)+1),"th","st","nd","rd","th")) -> 16th | F15: He is respectful and obedient | G15: Good result. Try to put more effort in your weak areas
A16: 9 | B16: =(sheet1!B17) -> EWELUKWA FAVOUR | C16: 118 | D16: =(sheet1!AP17) -> 63.117647 | E16: =RANK(D16,$D$8:$D$29)&IF(OR(RANK(D16,$D$8:$D$29)=11,RANK(D16,$D$8:$D$29)=12,RANK(D16,$D$8:$D$29)=13),"th",CHOOSE(MIN(5,MOD(RANK(D16,$D$8:$D$29),10)+1),"th","st","nd","rd","th")) -> 5th | F16: She is brilliant and industrious | G16: Very good. You have performed so well. Keep up the good work
A17: 10 | B17: =(sheet1!B18) -> HAMMED OLAMIDE | C17: 104 | D17: =(sheet1!AP18) -> 24.235294 | E17: =RANK(D17,$D$8:$D$29)&IF(OR(RANK(D17,$D$8:$D$29)=11,RANK(D17,$D$8:$D$29)=12,RANK(D17,$D$8:$D$29)=13),"th",CHOOSE(MIN(5,MOD(RANK(D17,$D$8:$D$29),10)+1),"th","st","nd","rd","th")) -> 22nd | F17: He is intelligent, obedient and hardworking | G17: Good performances. Work harder on your weak areas
A18: 11 | B18: =(sheet1!B19) -> HAMZAT AKOREDE | C18: 116 | D18: =(sheet1!AP19) -> 33.529412 | E18: =RANK(D18,$D$8:$D$29)&IF(OR(RANK(D18,$D$8:$D$29)=11,RANK(D18,$D$8:$D$29)=12,RANK(D18,$D$8:$D$29)=13),"th",CHOOSE(MIN(5,MOD(RANK(D18,$D$8:$D$29),10)+1),"th","st","nd","rd","th")) -> 21st | F18: He is brilliant, hardworking and industrious | G18: Good result but you can do better than this
A19: 12 | B19: =(sheet1!B20) -> JAMES DIVINE | C19: 122 | D19: =(sheet1!AP20) -> 37.882353 | E19: =RANK(D19,$D$8:$D$29)&IF(OR(RANK(D19,$D$8:$D$29)=11,RANK(D19,$D$8:$D$29)=12,RANK(D19,$D$8:$D$29)=13),"th",CHOOSE(MIN(5,MOD(RANK(D19,$D$8:$D$29),10)+1),"th","st","nd","rd","th")) -> 17th | F19: He is well behaved and intelligent | G19: Very good result. Keep it up
A20: 13 | B20: =(sheet1!B21) -> JOEL JOSHUA | C20: 110 | D20: =(sheet1!AP21) -> 51.352941 | E20: =RANK(D20,$D$8:$D$29)&IF(OR(RANK(D20,$D$8:$D$29)=11,RANK(D20,$D$8:$D$29)=12,RANK(D20,$D$8:$D$29)=13),"th",CHOOSE(MIN(5,MOD(RANK(D20,$D$8:$D$29),10)+1),"th","st","nd","rd","th")) -> 10th | F20: He is hard working and always punctual to school | G20: Excellent. Keep it up
A21: 14 | B21: =(sheet1!B22) -> JOSIAH SUNDAY | C21: 116 | D21: =(sheet1!AP22) -> 50.176471 | E21: =RANK(D21,$D$8:$D$29)&IF(OR(RANK(D21,$D$8:$D$29)=11,RANK(D21,$D$8:$D$29)=12,RANK(D21,$D$8:$D$29)=13),"th",CHOOSE(MIN(5,MOD(RANK(D21,$D$8:$D$29),10)+1),"th","st","nd","rd","th")) -> 11th | F21: He is truthful and reliable | G21: Poor result. You can do better next term
A22: 15 | B22: =(sheet1!B23) -> KUFRE GOODNEWS | C22: 118 | D22: =(sheet1!AP23) -> 37.176471 | E22: =RANK(D22,$D$8:$D$29)&IF(OR(RANK(D22,$D$8:$D$29)=11,RANK(D22,$D$8:$D$29)=12,RANK(D22,$D$8:$D$29)=13),"th",CHOOSE(MIN(5,MOD(RANK(D22,$D$8:$D$29),10)+1),"th","st","nd","rd","th")) -> 18th | F22: He is always attentive in the class | G22: Fairly good result. You can do better
A23: 16 | B23: =(sheet1!B24) -> NWABUEZE FAVOUR | C23: 126 | D23: =(sheet1!AP24) -> 65.941176 | E23: =RANK(D23,$D$8:$D$29)&IF(OR(RANK(D23,$D$8:$D$29)=11,RANK(D23,$D$8:$D$29)=12,RANK(D23,$D$8:$D$29)=13),"th",CHOOSE(MIN(5,MOD(RANK(D23,$D$8:$D$29),10)+1),"th","st","nd","rd","th")) -> 4th | F23: He is punctual to school and well behaved | G23: Fairly good. Buckle up next term
A24: 17 | B24: =(sheet1!B25) -> NWABUEZE VICTOR | C24: 116 | D24: =(sheet1!AP25) -> 47.176471 | E24: =RANK(D24,$D$8:$D$29)&IF(OR(RANK(D24,$D$8:$D$29)=11,RANK(D24,$D$8:$D$29)=12,RANK(D24,$D$8:$D$29)=13),"th",CHOOSE(MIN(5,MOD(RANK(D24,$D$8:$D$29),10)+1),"th","st","nd","rd","th")) -> 15th | F24: He is quite, well behaved and always neat | G24: Good result. You can surpass this performance next term
... A29: 22 | B29: =(sheet1!B30) -> WASIU NIMOTALLAH | C29: 128 | D29: =(sheet1!AP30) -> 49.411765 | E29: =RANK(D29,$D$8:$D$29)&IF(OR(RANK(D29,$D$8:$D$29)=11,RANK(D29,$D$8:$D$29)=12,RANK(D29,$D$8:$D$29)=13),"th",CHOOSE(MIN(5,MOD(RANK(D29,$D$8:$D$29),10)+1),"th","st","nd","rd","th")) -> 13th | F29: He needs to pay more attention in class to improve his understanding. | G29: Poor result. Learn to devote time to private/personal studies
A30: 23 | B30: =(sheet1!B31) -> 0 | D30: =(sheet1!AP31) -> 0 | F30: She is improving gradually but needs to participate more in class discussions. | G30: Just fair. You can improve if only you will be more regular at school next term
A31: 24 | B31: =(sheet1!B32) -> 0 | D31: =(sheet1!AP32) -> 0 | F31: He should learn to submit assignments on time. | G31: A good result you still need to work harder on your present scores. Promoted to the Next Class.
A32: 25 | B32: =(sheet1!B33) -> 0 | D32: =(sheet1!AP33) -> 0 | F32: She can do better if she avoids distractions during lessons. | G32: Fairly good. Give greater attention to your study next term. Promoted to the Next Class.
A33: 26 | B33: =(sheet1!B34) -> 0 | D33: =(sheet1!AP34) -> 0 | F33: He is sometimes playful in class and needs to concentrate more. | G33: This is good result. Keep working hard. Promoted to the Next Class.
A34: 27 | B34: =(sheet1!B35) -> 0 | D34: =(sheet1!AP35) -> 0 | F34: She tries her best but needs to put in more effort in her weak subjects. | G34: This performance is satisfactory. Promoted to the Next Class.
A35: 28 | B35: =(sheet1!B36) -> 0 | D35: =(sheet1!AP36) -> 0 | F35: He is calm but should be more active in group work. | G35: Good performance. Keep it up. Promoted to the Next Class.
A36: 29 | B36: =(sheet1!B37) -> 0 | D36: =(sheet1!AP37) -> 0 | F36: She is responsible but needs to work on her handwriting. | G36: Fair result. You can improve in your weak subjects. Promoted to the Next Class.
A37: 30 | B37: =(sheet1!B38) -> 0 | D37: =(sheet1!AP38) -> 0 | F37: He is improving in behavior but still needs to avoid lateness. | G37: Fairly good result. You need to work extra hard in your weak subjects area. Promoted to the Next Class.
A38: 31 | B38: =(sheet1!B39) -> 0 | D38: =(sheet1!AP39) -> 0 | F38: She is obedient but should learn to speak more confidently in class. | G38: Good result. Try to put more effort in your weak areas. Promoted to the Next Class.
A39: 32 | B39: =(sheet1!B40) -> 0 | D39: =(sheet1!AP40) -> 0 | F39: He shows interest in learning but needs to be more consistent. | G39: Very good. You have performed so well. Keep up the good work. Promoted to the Next Class.
A40: 33 | B40: =(sheet1!B41) -> 0 | D40: =(sheet1!AP41) -> 0 | F40: She is friendly but talks too much during lessons. | G40: Good performances. Work harder on your weak areas. Promoted to the Next Class.
A41: 34 | B41: =(sheet1!B42) -> 0 | D41: =(sheet1!AP42) -> 0 | F41: He needs to be more serious with his studies to achieve better results. | G41: Good result but you can do better than this. Promoted to the Next Class.
... A47: 40 | B47: =(sheet1!B48) -> 0 | D47: =(sheet1!AP48) -> 0 | F47: She can do better if she avoids distractions during lessons. | G47: Good result. You can surpass this performance next term. Promoted to the Next Class.
F48: He is sometimes playful in class and needs to concentrate more. | G48: Poor. Improve more on your studies to measure up. Learning is not difficult. Promoted to the Next Class.
F49: She tries her best but needs to put in more effort in her weak subjects. | G49: Excellent performance. Promoted to the Next Class.
F50: He is calm but should be more active in group work. | G50: Good result. You can improve on this next term. Promoted to the Next Class.
...

Sheet sheet3
B1: EASYNETT INT'L COLLEGE OF TECH.
B3: 76, WILMER CRESCENT, OLODI-APAPA, LAGOS
B4: TEL: 07030903097, 08054260717
B5: REPORT CARD
J7: PASSPORT PHOTO
A9: Student Name: | C9: =(sheet1!B9) -> ADAKARAZA SAMUEL
A10: Class: | C10: =(sheet1!B7) -> JSS 1A
A11: Session: | C11: =(sheet1!C4) -> 2025/2026
A12: Term: | C12: =(sheet1!B5) -> FIRST TERM | F12: Average Score: | H12: =VLOOKUP(C9,sheet2!B8:E47,3,FALSE) -> 35.058824
A13: Next Term Begins: | C13: =(sheet2!E6) -> 12TH JANUARY 2026 | F13: Position: | H13: =VLOOKUP(C9,sheet2!B8:E47,4,FALSE) -> 19th
A15: FREQUENCIES | D15: SCHOOL ATTENDANCE | G15: PSYCHOMOTOR | H15: PUNCTUALITY | J15: D
A16: No. of times School Opened: | D16: =(sheet2!C6) -> 128 | H16: NEATNESS | J16: C
A17: No. of times Present: | D17: =VLOOKUP(C9,sheet2!B8:C47,2,FALSE) -> 118 | H17: HONESTY | J17: C
A18: No. in Class: | D18: =(sheet2!D6) -> 22 | H18: CREATIVITY | J18: D
A20: SUBJECT | H20: CA | I20: EXAM | J20: TOTAL | K20: GRADE
A21: AGRICULTURAL SCIENCE | H21: =VLOOKUP(C9,sheet1!B9:AN48,2,FALSE) -> 28 | I21: =VLOOKUP(C9,sheet1!B9:AN48,3,FALSE) -> 28 | J21: =SUM(H21:I21) -> 56 | K21: =IF(J21>=70,"A",IF(J21>=50,"C",IF(J21>=40,"P","F"))) -> C
A22: BASIC SCIENCE | H22: =VLOOKUP(C9,sheet1!B9:AN48,4,FALSE) -> 28 | I22: =VLOOKUP(C9,sheet1!B9:AN48,5,FALSE) -> 28 | J22: =SUM(H22:I22) -> 56 | K22: =IF(J22>=70,"A",IF(J22>=50,"C",IF(J22>=40,"P","F"))) -> C
A23: BASIC TECH | H23: =VLOOKUP(C9,sheet1!B9:AN48,6,FALSE) -> 17 | I23: =VLOOKUP(C9,sheet1!B9:AN48,7,FALSE) -> 8 | J23: =SUM(H23:I23) -> 25 | K23: =IF(J23>=70,"A",IF(J23>=50,"C",IF(J23>=40,"P","F"))) -> F
A24: BUSINESS STUDIES | H24: =VLOOKUP(C9,sheet1!B9:AN48,8,FALSE) -> 17 | I24: =VLOOKUP(C9,sheet1!B9:AN48,9,FALSE) -> 15 | J24: =SUM(H24:I24) -> 32 | K24: =IF(J24>=70,"A",IF(J24>=50,"C",IF(J24>=40,"P","F"))) -> F
A25: CULTURAL & CREATIVE ART | H25: =VLOOKUP(C9,sheet1!B9:AN48,10,FALSE) -> 13 | I25: =VLOOKUP(C9,sheet1!B9:AN48,11,FALSE) -> 20 | J25: =SUM(H25:I25) -> 33 | K25: =IF(J25>=70,"A",IF(J25>=50,"C",IF(J25>=40,"P","F"))) -> F
A26: CIVIC EDUCATION | H26: =VLOOKUP(C9,sheet1!B9:AN48,12,FALSE) -> 17 | I26: =VLOOKUP(C9,sheet1!B9:AN48,13,FALSE) -> 10 | J26: =SUM(H26:I26) -> 27 | K26: =IF(J26>=70,"A",IF(J26>=50,"C",IF(J26>=40,"P","F"))) -> F
A27: CHRISTIAN RELIGIOUS STUDIES | H27: =VLOOKUP(C9,sheet1!B9:AN48,14,FALSE) -> 21 | I27: =VLOOKUP(C9,sheet1!B9:AN48,15,FALSE) -> 30 | J27: =SUM(H27:I27) -> 51 | K27: =IF(J27>=70,"A",IF(J27>=50,"C",IF(J27>=40,"P","F"))) -> C
A28: ENGLISH LANGUAGE | H28: =VLOOKUP(C9,sheet1!B9:AN48,16,FALSE) -> 13 | I28: =VLOOKUP(C9,sheet1!B9:AN48,17,FALSE) -> 11 | J28: =SUM(H28:I28) -> 24 | K28: =IF(J28>=70,"A",IF(J28>=50,"C",IF(J28>=40,"P","F"))) -> F
A29: ENGLISH PHONETICS | H29: =VLOOKUP(C9,sheet1!B9:AN48,18,FALSE) -> 0 | I29: =VLOOKUP(C9,sheet1!B9:AN48,19,FALSE) -> 0 | J29: =SUM(H29:I29) -> 0 | K29: =IF(J29>=70,"A",IF(J29>=50,"C",IF(J29>=40,"P","F"))) -> F
A30: FRENCH | H30: =VLOOKUP(C9,sheet1!B9:AN48,20,FALSE) -> 17 | I30: =VLOOKUP(C9,sheet1!B9:AN48,21,FALSE) -> 6 | J30: =SUM(H30:I30) -> 23 | K30: =IF(J30>=70,"A",IF(J30>=50,"C",IF(J30>=40,"P","F"))) -> F
A31: HISTORY | H31: =VLOOKUP(C9,sheet1!B9:AN48,22,FALSE) -> 15 | I31: =VLOOKUP(C9,sheet1!B9:AN48,23,FALSE) -> 11 | J31: =SUM(H31:I31) -> 26 | K31: =IF(J31>=70,"A",IF(J31>=50,"C",IF(J31>=40,"P","F"))) -> F
A32: HOME ECONOMICS | H32: =VLOOKUP(C9,sheet1!B9:AN48,24,FALSE) -> 20 | I32: =VLOOKUP(C9,sheet1!B9:AN48,25,FALSE) -> 24 | J32: =SUM(H32:I32) -> 44 | K32: =IF(J32>=70,"A",IF(J32>=50,"C",IF(J32>=40,"P","F"))) -> P
A33: IGBO LANGUAGE | H33: =VLOOKUP(C9,sheet1!B9:AN48,26,FALSE) -> 0 | I33: =VLOOKUP(C9,sheet1!B9:AN48,27,FALSE) -> 0 | J33: =SUM(H33:I33) -> 0 | K33: =IF(J33>=70,"A",IF(J33>=50,"C",IF(J33>=40,"P","F"))) -> F
A34: INFORMATION TECHNOLOGY | H34: =VLOOKUP(C9,sheet1!B9:AN48,28,FALSE) -> 18 | I34: =VLOOKUP(C9,sheet1!B9:AN48,29,FALSE) -> 10 | J34: =SUM(H34:I34) -> 28 | K34: =IF(J34>=70,"A",IF(J34>=50,"C",IF(J34>=40,"P","F"))) -> F
A35: MATHEMATICS | H35: =VLOOKUP(C9,sheet1!B9:AN48,30,FALSE) -> 20 | I35: =VLOOKUP(C9,sheet1!B9:AN48,31,FALSE) -> 20 | J35: =SUM(H35:I35) -> 40 | K35: =IF(J35>=70,"A",IF(J35>=50,"C",IF(J35>=40,"P","F"))) -> P
A36: PHYSICAL & HEALTH EDUCATION | H36: =VLOOKUP(C9,sheet1!B9:AN48,32,FALSE) -> 29 | I36: =VLOOKUP(C9,sheet1!B9:AN48,33,FALSE) -> 10 | J36: =SUM(H36:I36) -> 39 | K36: =IF(J36>=70,"A",IF(J36>=50,"C",IF(J36>=40,"P","F"))) -> F
A37: SECURITY EDUCATION | H37: =VLOOKUP(C9,sheet1!B9:AN48,34,FALSE) -> 15 | I37: =VLOOKUP(C9,sheet1!B9:AN48,35,FALSE) -> 3 | J37: =SUM(H37:I37) -> 18 | K37: =IF(J37>=70,"A",IF(J37>=50,"C",IF(J37>=40,"P","F"))) -> F
A38: SOCIAL STUDIES | H38: =VLOOKUP(C9,sheet1!B9:AN48,36,FALSE) -> 15 | I38: =VLOOKUP(C9,sheet1!B9:AN48,37,FALSE) -> 16 | J38: =SUM(H38:I38) -> 31 | K38: =IF(J38>=70,"A",IF(J38>=50,"C",IF(J38>=40,"P","F"))) -> F
A39: YORUBA LANGUAGE | H39: =VLOOKUP(C9,sheet1!B9:AN48,38,FALSE) -> 21 | I39: =VLOOKUP(C9,sheet1!B9:AN48,39,FALSE) -> 22 | J39: =SUM(H39:I39) -> 43 | K39: =IF(J39>=70,"A",IF(J39>=50,"C",IF(J39>=40,"P","F"))) -> P
G45: SIGNATURE & STAMP
A46: CLASS TEACHER'S REMARK:
A47: He can perform better with greater commitment and focus.
A49: PRINCIPAL'S COMMENT:
A50: Poor result. Learn to devote time to private/personal studies
A53: KEYS TO GRADE:
...

Sheet sheet4
B1: EASYNETT INT'L COLLEGE OF TECH.
B3: 76, WILMER CRESCENT, OLODI-APAPA, LAGOS
B4: TEL: 07030903097, 08054260717
B5: REPORT CARD
J7: PASSPORT PHOTO
A9: Student Name: | C9: =(sheet1!B10) -> ADEOLA PEDRO
A10: Class: | C10: =(sheet1!B7) -> JSS 1A
A11: Session: | C11: =(sheet1!C4) -> 2025/2026
A12: Term: | C12: =(sheet1!B5) -> FIRST TERM | F12: Average Score: | H12: =VLOOKUP(C9,sheet2!B8:E47,3,FALSE) -> 49.764706
A13: Next Term Begins: | C13: =(sheet2!E6) -> 12TH JANUARY 2026 | F13: Position: | H13: =VLOOKUP(C9,sheet2!B8:E47,4,FALSE) -> 12th
A15: FREQUENCIES | D15: SCHOOL ATTENDANCE | G15: PSYCHOMOTOR | H15: PUNCTUALITY | J15: A
A16: No. of times School Opened: | D16: =(sheet2!C6) -> 128 | H16: NEATNESS | J16: B
A17: No. of times Present: | D17: =VLOOKUP(C9,sheet2!B8:C47,2,FALSE) -> 128 | H17: HONESTY | J17: A
A18: No. in Class: | D18: =(sheet2!D6) -> 22 | H18: CREATIVITY | J18: C
A20: SUBJECT | H20: CA | I20: EXAM | J20: TOTAL | K20: GRADE
A21: AGRICULTURAL SCIENCE | H21: =VLOOKUP(C9,sheet1!B9:AN48,2,FALSE) -> 28 | I21: =VLOOKUP(C9,sheet1!B9:AN48,3,FALSE) -> 39 | J21: =SUM(H21:I21) -> 67 | K21: =IF(J21>=70,"A",IF(J21>=50,"C",IF(J21>=40,"P","F"))) -> C
A22: BASIC SCIENCE | H22: =VLOOKUP(C9,sheet1!B9:AN48,4,FALSE) -> 25 | I22: =VLOOKUP(C9,sheet1!B9:AN48,5,FALSE) -> 39 | J22: =SUM(H22:I22) -> 64 | K22: =IF(J22>=70,"A",IF(J22>=50,"C",IF(J22>=40,"P","F"))) -> C
A23: BASIC TECH | H23: =VLOOKUP(C9,sheet1!B9:AN48,6,FALSE) -> 20 | I23: =VLOOKUP(C9,sheet1!B9:AN48,7,FALSE) -> 22 | J23: =SUM(H23:I23) -> 42 | K23: =IF(J23>=70,"A",IF(J23>=50,"C",IF(J23>=40,"P","F"))) -> P
A24: BUSINESS STUDIES | H24: =VLOOKUP(C9,sheet1!B9:AN48,8,FALSE) -> 24 | I24: =VLOOKUP(C9,sheet1!B9:AN48,9,FALSE) -> 23 | J24: =SUM(H24:I24) -> 47 | K24: =IF(J24>=70,"A",IF(J24>=50,"C",IF(J24>=40,"P","F"))) -> P
A25: CULTURAL & CREATIVE ART | H25: =VLOOKUP(C9,sheet1!B9:AN48,10,FALSE) -> 21 | I25: =VLOOKUP(C9,sheet1!B9:AN48,11,FALSE) -> 20 | J25: =SUM(H25:I25) -> 41 | K25: =IF(J25>=70,"A",IF(J25>=50,"C",IF(J25>=40,"P","F"))) -> P
A26: CIVIC EDUCATION | H26: =VLOOKUP(C9,sheet1!B9:AN48,12,FALSE) -> 24 | I26: =VLOOKUP(C9,sheet1!B9:AN48,13,FALSE) -> 10 | J26: =SUM(H26:I26) -> 34 | K26: =IF(J26>=70,"A",IF(J26>=50,"C",IF(J26>=40,"P","F"))) -> F
A27: CHRISTIAN RELIGIOUS STUDIES | H27: =VLOOKUP(C9,sheet1!B9:AN48,14,FALSE) -> 20 | I27: =VLOOKUP(C9,sheet1!B9:AN48,15,FALSE) -> 30 | J27: =SUM(H27:I27) -> 50 | K27: =IF(J27>=70,"A",IF(J27>=50,"C",IF(J27>=40,"P","F"))) -> C
A28: ENGLISH LANGUAGE | H28: =VLOOKUP(C9,sheet1!B9:AN48,16,FALSE) -> 24 | I28: =VLOOKUP(C9,sheet1!B9:AN48,17,FALSE) -> 25 | J28: =SUM(H28:I28) -> 49 | K28: =IF(J28>=70,"A",IF(J28>=50,"C",IF(J28>=40,"P","F"))) -> P
A29: ENGLISH PHONETICS | H29: =VLOOKUP(C9,sheet1!B9:AN48,18,FALSE) -> 0 | I29: =VLOOKUP(C9,sheet1!B9:AN48,19,FALSE) -> 0 | J29: =SUM(H29:I29) -> 0 | K29: =IF(J29>=70,"A",IF(J29>=50,"C",IF(J29>=40,"P","F"))) -> F
A30: FRENCH | H30: =VLOOKUP(C9,sheet1!B9:AN48,20,FALSE) -> 22 | I30: =VLOOKUP(C9,sheet1!B9:AN48,21,FALSE) -> 37 | J30: =SUM(H30:I30) -> 59 | K30: =IF(J30>=70,"A",IF(J30>=50,"C",IF(J30>=40,"P","F"))) -> C
A31: HISTORY | H31: =VLOOKUP(C9,sheet1!B9:AN48,22,FALSE) -> 28 | I31: =VLOOKUP(C9,sheet1!B9:AN48,23,FALSE) -> 36 | J31: =SUM(H31:I31) -> 64 | K31: =IF(J31>=70,"A",IF(J31>=50,"C",IF(J31>=40,"P","F"))) -> C
A32: HOME ECONOMICS | H32: =VLOOKUP(C9,sheet1!B9:AN48,24,FALSE) -> 25 | I32: =VLOOKUP(C9,sheet1!B9:AN48,25,FALSE) -> 30 | J32: =SUM(H32:I32) -> 55 | K32: =IF(J32>=70,"A",IF(J32>=50,"C",IF(J32>=40,"P","F"))) -> C
A33: IGBO LANGUAGE | H33: =VLOOKUP(C9,sheet1!B9:AN48,26,FALSE) -> 0 | I33: =VLOOKUP(C9,sheet1!B9:AN48,27,FALSE) -> 0 | J33: =SUM(H33:I33) -> 0 | K33: =IF(J33>=70,"A",IF(J33>=50,"C",IF(J33>=40,"P","F"))) -> F
A34: INFORMATION TECHNOLOGY | H34: =VLOOKUP(C9,sheet1!B9:AN48,28,FALSE) -> 24 | I34: =VLOOKUP(C9,sheet1!B9:AN48,29,FALSE) -> 29 | J34: =SUM(H34:I34) -> 53 | K34: =IF(J34>=70,"A",IF(J34>=50,"C",IF(J34>=40,"P","F"))) -> C
A35: MATHEMATICS | H35: =VLOOKUP(C9,sheet1!B9:AN48,30,FALSE) -> 20 | I35: =VLOOKUP(C9,sheet1!B9:AN48,31,FALSE) -> 20 | J35: =SUM(H35:I35) -> 40 | K35: =IF(J35>=70,"A",IF(J35>=50,"C",IF(J35>=40,"P","F"))) -> P
A36: PHYSICAL & HEALTH EDUCATION | H36: =VLOOKUP(C9,sheet1!B9:AN48,32,FALSE) -> 29 | I36: =VLOOKUP(C9,sheet1!B9:AN48,33,FALSE) -> 28 | J36: =SUM(H36:I36) -> 57 | K36: =IF(J36>=70,"A",IF(J36>=50,"C",IF(J36>=40,"P","F"))) -> C
A37: SECURITY EDUCATION | H37: =VLOOKUP(C9,sheet1!B9:AN48,34,FALSE) -> 17 | I37: =VLOOKUP(C9,sheet1!B9:AN48,35,FALSE) -> 4 | J37: =SUM(H37:I37) -> 21 | K37: =IF(J37>=70,"A",IF(J37>=50,"C",IF(J37>=40,"P","F"))) -> F
A38: SOCIAL STUDIES | H38: =VLOOKUP(C9,sheet1!B9:AN48,36,FALSE) -> 14 | I38: =VLOOKUP(C9,sheet1!B9:AN48,37,FALSE) -> 22 | J38: =SUM(H38:I38) -> 36 | K38: =IF(J38>=70,"A",IF(J38>=50,"C",IF(J38>=40,"P","F"))) -> F
A39: YORUBA LANGUAGE | H39: =VLOOKUP(C9,sheet1!B9:AN48,38,FALSE) -> 27 | I39: =VLOOKUP(C9,sheet1!B9:AN48,39,FALSE) -> 40 | J39: =SUM(H39:I39) -> 67 | K39: =IF(J39>=70,"A",IF(J39>=50,"C",IF(J39>=40,"P","F"))) -> C
G45: SIGNATURE & STAMP
A46: CLASS TEACHER'S REMARK:
A47: He shows interest in learning but needs to be more consistent.
A49: PRINCIPAL'S COMMENT:
A50: Fairly good. Buckle up next term
A53: KEYS TO GRADE:
...

Sheet sheet5
B1: EASYNETT INT'L COLLEGE OF TECH.
B3: 76, WILMER CRESCENT, OLODI-APAPA, LAGOS
B4: TEL: 07030903097, 08054260717
B5: REPORT CARD
J7: PASSPORT PHOTO
A9: Student Name: | C9: =(sheet1!B11) -> ASAMS DANIELLA
A10: Class: | C10: =(sheet1!B7) -> JSS 1A
A11: Session: | C11: =(sheet1!C4) -> 2025/2026
A12: Term: | C12: =(sheet1!B5) -> FIRST TERM | F12: Average Score: | H12: =VLOOKUP(C9,sheet2!B8:E47,3,FALSE) -> 59.588235
A13: Next Term Begins: | C13: =(sheet2!E6) -> 12TH JANUARY 2026 | F13: Position: | H13: =VLOOKUP(C9,sheet2!B8:E47,4,FALSE) -> 7th
A15: FREQUENCIES | D15: SCHOOL ATTENDANCE | G15: PSYCHOMOTOR | H15: PUNCTUALITY | J15: A
A16: No. of times School Opened: | D16: =(sheet2!C6) -> 128 | H16: NEATNESS | J16: B
A17: No. of times Present: | D17: =VLOOKUP(C9,sheet2!B8:C47,2,FALSE) -> 126 | H17: HONESTY | J17: A
A18: No. in Class: | D18: =(sheet2!D6) -> 22 | H18: CREATIVITY | J18: C
A20: SUBJECT | H20: CA | I20: EXAM | J20: TOTAL | K20: GRADE
A21: AGRICULTURAL SCIENCE | H21: =VLOOKUP(C9,sheet1!B9:AN48,2,FALSE) -> 28 | I21: =VLOOKUP(C9,sheet1!B9:AN48,3,FALSE) -> 35 | J21: =SUM(H21:I21) -> 63 | K21: =IF(J21>=70,"A",IF(J21>=50,"C",IF(J21>=40,"P","F"))) -> C
A22: BASIC SCIENCE | H22: =VLOOKUP(C9,sheet1!B9:AN48,4,FALSE) -> 25 | I22: =VLOOKUP(C9,sheet1!B9:AN48,5,FALSE) -> 55 | J22: =SUM(H22:I22) -> 80 | K22: =IF(J22>=70,"A",IF(J22>=50,"C",IF(J22>=40,"P","F"))) -> A
A23: BASIC TECH | H23: =VLOOKUP(C9,sheet1!B9:AN48,6,FALSE) -> 22 | I23: =VLOOKUP(C9,sheet1!B9:AN48,7,FALSE) -> 60 | J23: =SUM(H23:I23) -> 82 | K23: =IF(J23>=70,"A",IF(J23>=50,"C",IF(J23>=40,"P","F"))) -> A
A24: BUSINESS STUDIES | H24: =VLOOKUP(C9,sheet1!B9:AN48,8,FALSE) -> 18 | I24: =VLOOKUP(C9,sheet1!B9:AN48,9,FALSE) -> 22 | J24: =SUM(H24:I24) -> 40 | K24: =IF(J24>=70,"A",IF(J24>=50,"C",IF(J24>=40,"P","F"))) -> P
A25: CULTURAL & CREATIVE ART | H25: =VLOOKUP(C9,sheet1!B9:AN48,10,FALSE) -> 20 | I25: =VLOOKUP(C9,sheet1!B9:AN48,11,FALSE) -> 20 | J25: =SUM(H25:I25) -> 40 | K25: =IF(J25>=70,"A",IF(J25>=50,"C",IF(J25>=40,"P","F"))) -> P
A26: CIVIC EDUCATION | H26: =VLOOKUP(C9,sheet1!B9:AN48,12,FALSE) -> 17 | I26: =VLOOKUP(C9,sheet1!B9:AN48,13,FALSE) -> 38 | J26: =SUM(H26:I26) -> 55 | K26: =IF(J26>=70,"A",IF(J26>=50,"C",IF(J26>=40,"P","F"))) -> C
A27: CHRISTIAN RELIGIOUS STUDIES | H27: =VLOOKUP(C9,sheet1!B9:AN48,14,FALSE) -> 28 | I27: =VLOOKUP(C9,sheet1!B9:AN48,15,FALSE) -> 45 | J27: =SUM(H27:I27) -> 73 | K27: =IF(J27>=70,"A",IF(J27>=50,"C",IF(J27>=40,"P","F"))) -> A
A28: ENGLISH LANGUAGE | H28: =VLOOKUP(C9,sheet1!B9:AN48,16,FALSE) -> 23 | I28: =VLOOKUP(C9,sheet1!B9:AN48,17,FALSE) -> 52 | J28: =SUM(H28:I28) -> 75 | K28: =IF(J28>=70,"A",IF(J28>=50,"C",IF(J28>=40,"P","F"))) -> A
A29: ENGLISH PHONETICS | H29: =VLOOKUP(C9,sheet1!B9:AN48,18,FALSE) -> 0 | I29: =VLOOKUP(C9,sheet1!B9:AN48,19,FALSE) -> 0 | J29: =SUM(H29:I29) -> 0 | K29: =IF(J29>=70,"A",IF(J29>=50,"C",IF(J29>=40,"P","F"))) -> F
A30: FRENCH | H30: =VLOOKUP(C9,sheet1!B9:AN48,20,FALSE) -> 20 | I30: =VLOOKUP(C9,sheet1!B9:AN48,21,FALSE) -> 43 | J30: =SUM(H30:I30) -> 63 | K30: =IF(J30>=70,"A",IF(J30>=50,"C",IF(J30>=40,"P","F"))) -> C
A31: HISTORY | H31: =VLOOKUP(C9,sheet1!B9:AN48,22,FALSE) -> 26 | I31: =VLOOKUP(C9,sheet1!B9:AN48,23,FALSE) -> 35 | J31: =SUM(H31:I31) -> 61 | K31: =IF(J31>=70,"A",IF(J31>=50,"C",IF(J31>=40,"P","F"))) -> C
A32: HOME ECONOMICS | H32: =VLOOKUP(C9,sheet1!B9:AN48,24,FALSE) -> 25 | I32: =VLOOKUP(C9,sheet1!B9:AN48,25,FALSE) -> 31 | J32: =SUM(H32:I32) -> 56 | K32: =IF(J32>=70,"A",IF(J32>=50,"C",IF(J32>=40,"P","F"))) -> C
A33: IGBO LANGUAGE | H33: =VLOOKUP(C9,sheet1!B9:AN48,26,FALSE) -> 0 | I33: =VLOOKUP(C9,sheet1!B9:AN48,27,FALSE) -> 0 | J33: =SUM(H33:I33) -> 0 | K33: =IF(J33>=70,"A",IF(J33>=50,"C",IF(J33>=40,"P","F"))) -> F
A34: INFORMATION TECHNOLOGY | H34: =VLOOKUP(C9,sheet1!B9:AN48,28,FALSE) -> 18 | I34: =VLOOKUP(C9,sheet1!B9:AN48,29,FALSE) -> 37 | J34: =SUM(H34:I34) -> 55 | K34: =IF(J34>=70,"A",IF(J34>=50,"C",IF(J34>=40,"P","F"))) -> C
A35: MATHEMATICS | H35: =VLOOKUP(C9,sheet1!B9:AN48,30,FALSE) -> 20 | I35: =VLOOKUP(C9,sheet1!B9:AN48,31,FALSE) -> 30 | J35: =SUM(H35:I35) -> 50 | K35: =IF(J35>=70,"A",IF(J35>=50,"C",IF(J35>=40,"P","F"))) -> C
A36: PHYSICAL & HEALTH EDUCATION | H36: =VLOOKUP(C9,sheet1!B9:AN48,32,FALSE) -> 26 | I36: =VLOOKUP(C9,sheet1!B9:AN48,33,FALSE) -> 32 | J36: =SUM(H36:I36) -> 58 | K36: =IF(J36>=70,"A",IF(J36>=50,"C",IF(J36>=40,"P","F"))) -> C
A37: SECURITY EDUCATION | H37: =VLOOKUP(C9,sheet1!B9:AN48,34,FALSE) -> 20 | I37: =VLOOKUP(C9,sheet1!B9:AN48,35,FALSE) -> 25 | J37: =SUM(H37:I37) -> 45 | K37: =IF(J37>=70,"A",IF(J37>=50,"C",IF(J37>=40,"P","F"))) -> P
A38: SOCIAL STUDIES | H38: =VLOOKUP(C9,sheet1!B9:AN48,36,FALSE) -> 20 | I38: =VLOOKUP(C9,sheet1!B9:AN48,37,FALSE) -> 31 | J38: =SUM(H38:I38) -> 51 | K38: =IF(J38>=70,"A",IF(J38>=50,"C",IF(J38>=40,"P","F"))) -> C
A39: YORUBA LANGUAGE | H39: =VLOOKUP(C9,sheet1!B9:AN48,38,FALSE) -> 26 | I39: =VLOOKUP(C9,sheet1!B9:AN48,39,FALSE) -> 40 | J39: =SUM(H39:I39) -> 66 | K39: =IF(J39>=70,"A",IF(J39>=50,"C",IF(J39>=40,"P","F"))) -> C
G45: SIGNATURE & STAMP
A46: CLASS TEACHER'S REMARK:
A47: She tries her best but needs to put in more effort in her weak subjects.
A49: PRINCIPAL'S COMMENT:
A50: Good result. You can surpass this performance next term
A54: KEYS TO GRADE:
...

Sheet sheet6
B1: EASYNETT INT'L COLLEGE OF TECH.
B3: 76, WILMER CRESCENT, OLODI-APAPA, LAGOS
B4: TEL: 07030903097, 08054260717
B5: REPORT CARD
J7: PASSPORT PHOTO
A9: Student Name: | C9: =(sheet1!B12) -> ASIBOR NANCY
A10: Class: | C10: =(sheet1!B7) -> JSS 1A
A11: Session: | C11: =(sheet1!C4) -> 2025/2026
A12: Term: | C12: =(sheet1!B5) -> FIRST TERM | F12: Average Score: | H12: =VLOOKUP(C9,sheet2!B8:E47,3,FALSE) -> 59.117647
A13: Next Term Begins: | C13: =(sheet2!E6) -> 12TH JANUARY 2026 | F13: Position: | H13: =VLOOKUP(C9,sheet2!B8:E47,4,FALSE) -> 8th
A15: FREQUENCIES | D15: SCHOOL ATTENDANCE | G15: PSYCHOMOTOR | H15: PUNCTUALITY | J15: A
A16: No. of times School Opened: | D16: =(sheet2!C6) -> 128 | H16: NEATNESS | J16: A
A17: No. of times Present: | D17: =VLOOKUP(C9,sheet2!B8:C47,2,FALSE) -> 108 | H17: HONESTY | J17: A
A18: No. in Class: | D18: =(sheet2!D6) -> 22 | H18: CREATIVITY | J18: B
A20: SUBJECT | H20: CA | I20: EXAM | J20: TOTAL | K20: GRADE
A21: AGRICULTURAL SCIENCE | H21: =VLOOKUP(C9,sheet1!B9:AN48,2,FALSE) -> 28 | I21: =VLOOKUP(C9,sheet1!B9:AN48,3,FALSE) -> 50 | J21: =SUM(H21:I21) -> 78 | K21: =IF(J21>=70,"A",IF(J21>=50,"C",IF(J21>=40,"P","F"))) -> A
A22: BASIC SCIENCE | H22: =VLOOKUP(C9,sheet1!B9:AN48,4,FALSE) -> 27 | I22: =VLOOKUP(C9,sheet1!B9:AN48,5,FALSE) -> 51 | J22: =SUM(H22:I22) -> 78 | K22: =IF(J22>=70,"A",IF(J22>=50,"C",IF(J22>=40,"P","F"))) -> A
A23: BASIC TECH | H23: =VLOOKUP(C9,sheet1!B9:AN48,6,FALSE) -> 20 | I23: =VLOOKUP(C9,sheet1!B9:AN48,7,FALSE) -> 30 | J23: =SUM(H23:I23) -> 50 | K23: =IF(J23>=70,"A",IF(J23>=50,"C",IF(J23>=40,"P","F"))) -> C
A24: BUSINESS STUDIES | H24: =VLOOKUP(C9,sheet1!B9:AN48,8,FALSE) -> 24 | I24: =VLOOKUP(C9,sheet1!B9:AN48,9,FALSE) -> 30 | J24: =SUM(H24:I24) -> 54 | K24: =IF(J24>=70,"A",IF(J24>=50,"C",IF(J24>=40,"P","F"))) -> C
A25: CULTURAL & CREATIVE ART | H25: =VLOOKUP(C9,sheet1!B9:AN48,10,FALSE) -> 29 | I25: =VLOOKUP(C9,sheet1!B9:AN48,11,FALSE) -> 38 | J25: =SUM(H25:I25) -> 67 | K25: =IF(J25>=70,"A",IF(J25>=50,"C",IF(J25>=40,"P","F"))) -> C
A26: CIVIC EDUCATION | H26: =VLOOKUP(C9,sheet1!B9:AN48,12,FALSE) -> 23 | I26: =VLOOKUP(C9,sheet1!B9:AN48,13,FALSE) -> 53 | J26: =SUM(H26:I26) -> 76 | K26: =IF(J26>=70,"A",IF(J26>=50,"C",IF(J26>=40,"P","F"))) -> A
A27: CHRISTIAN RELIGIOUS STUDIES | H27: =VLOOKUP(C9,sheet1!B9:AN48,14,FALSE) -> 23 | I27: =VLOOKUP(C9,sheet1!B9:AN48,15,FALSE) -> 36 | J27: =SUM(H27:I27) -> 59 | K27: =IF(J27>=70,"A",IF(J27>=50,"C",IF(J27>=40,"P","F"))) -> C
A28: ENGLISH LANGUAGE | H28: =VLOOKUP(C9,sheet1!B9:AN48,16,FALSE) -> 27 | I28: =VLOOKUP(C9,sheet1!B9:AN48,17,FALSE) -> 26 | J28: =SUM(H28:I28) -> 53 | K28: =IF(J28>=70,"A",IF(J28>=50,"C",IF(J28>=40,"P","F"))) -> C
A29: ENGLISH PHONETICS | H29: =VLOOKUP(C9,sheet1!B9:AN48,18,FALSE) -> 0 | I29: =VLOOKUP(C9,sheet1!B9:AN48,19,FALSE) -> 0 | J29: =SUM(H29:I29) -> 0 | K29: =IF(J29>=70,"A",IF(J29>=50,"C",IF(J29>=40,"P","F"))) -> F
A30: FRENCH | H30: =VLOOKUP(C9,sheet1!B9:AN48,20,FALSE) -> 10 | I30: =VLOOKUP(C9,sheet1!B9:AN48,21,FALSE) -> 44 | J30: =SUM(H30:I30) -> 54 | K30: =IF(J30>=70,"A",IF(J30>=50,"C",IF(J30>=40,"P","F"))) -> C
A31: HISTORY | H31: =VLOOKUP(C9,sheet1!B9:AN48,22,FALSE) -> 27 | I31: =VLOOKUP(C9,sheet1!B9:AN48,23,FALSE) -> 35 | J31: =SUM(H31:I31) -> 62 | K31: =IF(J31>=70,"A",IF(J31>=50,"C",IF(J31>=40,"P","F"))) -> C
A32: HOME ECONOMICS | H32: =VLOOKUP(C9,sheet1!B9:AN48,24,FALSE) -> 23 | I32: =VLOOKUP(C9,sheet1!B9:AN48,25,FALSE) -> 30 | J32: =SUM(H32:I32) -> 53 | K32: =IF(J32>=70,"A",IF(J32>=50,"C",IF(J32>=40,"P","F"))) -> C
A33: IGBO LANGUAGE | H33: =VLOOKUP(C9,sheet1!B9:AN48,26,FALSE) -> 0 | I33: =VLOOKUP(C9,sheet1!B9:AN48,27,FALSE) -> 0 | J33: =SUM(H33:I33) -> 0 | K33: =IF(J33>=70,"A",IF(J33>=50,"C",IF(J33>=40,"P","F"))) -> F
A34: INFORMATION TECHNOLOGY | H34: =VLOOKUP(C9,sheet1!B9:AN48,28,FALSE) -> 21 | I34: =VLOOKUP(C9,sheet1!B9:AN48,29,FALSE) -> 36 | J34: =SUM(H34:I34) -> 57 | K34: =IF(J34>=70,"A",IF(J34>=50,"C",IF(J34>=40,"P","F"))) -> C
A35: MATHEMATICS | H35: =VLOOKUP(C9,sheet1!B9:AN48,30,FALSE) -> 20 | I35: =VLOOKUP(C9,sheet1!B9:AN48,31,FALSE) -> 28 | J35: =SUM(H35:I35) -> 48 | K35: =IF(J35>=70,"A",IF(J35>=50,"C",IF(J35>=40,"P","F"))) -> P
A36: PHYSICAL & HEALTH EDUCATION | H36: =VLOOKUP(C9,sheet1!B9:AN48,32,FALSE) -> 26 | I36: =VLOOKUP(C9,sheet1!B9:AN48,33,FALSE) -> 40 | J36: =SUM(H36:I36) -> 66 | K36: =IF(J36>=70,"A",IF(J36>=50,"C",IF(J36>=40,"P","F"))) -> C
A37: SECURITY EDUCATION | H37: =VLOOKUP(C9,sheet1!B9:AN48,34,FALSE) -> 17 | I37: =VLOOKUP(C9,sheet1!B9:AN48,35,FALSE) -> 27 | J37: =SUM(H37:I37) -> 44 | K37: =IF(J37>=70,"A",IF(J37>=50,"C",IF(J37>=40,"P","F"))) -> P
A38: SOCIAL STUDIES | H38: =VLOOKUP(C9,sheet1!B9:AN48,36,FALSE) -> 20 | I38: =VLOOKUP(C9,sheet1!B9:AN48,37,FALSE) -> 41 | J38: =SUM(H38:I38) -> 61 | K38: =IF(J38>=70,"A",IF(J38>=50,"C",IF(J38>=40,"P","F"))) -> C
A39: YORUBA LANGUAGE | H39: =VLOOKUP(C9,sheet1!B9:AN48,38,FALSE) -> 19 | I39: =VLOOKUP(C9,sheet1!B9:AN48,39,FALSE) -> 26 | J39: =SUM(H39:I39) -> 45 | K39: =IF(J39>=70,"A",IF(J39>=50,"C",IF(J39>=40,"P","F"))) -> P
G45: SIGNATURE & STAMP
A46: CLASS TEACHER'S REMARK:
A47: She is hardworking, obedient and well behaved
A49: PRINCIPAL'S COMMENT:
A50: Just fair. You can improve if only you will be more regular at school next term. Promoted to the Next Class.
A53: KEYS TO GRADE:
...

Sheet sheet7
B1: EASYNETT INT'L COLLEGE OF TECH.
B3: 76, WILMER CRESCENT, OLODI-APAPA, LAGOS
B4: TEL: 07030903097, 08054260717
B5: REPORT CARD
J7: PASSPORT PHOTO
A9: Student Name: | C9: =(sheet1!B13) -> BANKOLE AMEERAT
A10: Class: | C10: =(sheet1!B7) -> JSS 1A
A11: Session: | C11: =(sheet1!C4) -> 2025/2026
A12: Term: | C12: =(sheet1!B5) -> FIRST TERM | F12: Average Score: | H12: =VLOOKUP(C9,sheet2!B8:E47,3,FALSE) -> 71.117647
A13: Next Term Begins: | C13: =(sheet2!E6) -> 12TH JANUARY 2026 | F13: Position: | H13: =VLOOKUP(C9,sheet2!B8:E47,4,FALSE) -> 1st
A15: FREQUENCIES | D15: SCHOOL ATTENDANCE | G15: PSYCHOMOTOR | H15: PUNCTUALITY | J15: A
A16: No. of times School Opened: | D16: =(sheet2!C6) -> 128 | H16: NEATNESS | J16: B
A17: No. of times Present: | D17: =VLOOKUP(C9,sheet2!B8:C47,2,FALSE) -> 128 | H17: HONESTY | J17: A
A18: No. in Class: | D18: =(sheet2!D6) -> 22 | H18: CREATIVITY | J18: B
A20: SUBJECT | H20: CA | I20: EXAM | J20: TOTAL | K20: GRADE
A21: AGRICULTURAL SCIENCE | H21: =VLOOKUP(C9,sheet1!B9:AN48,2,FALSE) -> 28 | I21: =VLOOKUP(C9,sheet1!B9:AN48,3,FALSE) -> 68 | J21: =SUM(H21:I21) -> 96 | K21: =IF(J21>=70,"A",IF(J21>=50,"C",IF(J21>=40,"P","F"))) -> A
A22: BASIC SCIENCE | H22: =VLOOKUP(C9,sheet1!B9:AN48,4,FALSE) -> 28 | I22: =VLOOKUP(C9,sheet1!B9:AN48,5,FALSE) -> 66 | J22: =SUM(H22:I22) -> 94 | K22: =IF(J22>=70,"A",IF(J22>=50,"C",IF(J22>=40,"P","F"))) -> A
A23: BASIC TECH | H23: =VLOOKUP(C9,sheet1!B9:AN48,6,FALSE) -> 22 | I23: =VLOOKUP(C9,sheet1!B9:AN48,7,FALSE) -> 52 | J23: =SUM(H23:I23) -> 74 | K23: =IF(J23>=70,"A",IF(J23>=50,"C",IF(J23>=40,"P","F"))) -> A
A24: BUSINESS STUDIES | H24: =VLOOKUP(C9,sheet1!B9:AN48,8,FALSE) -> 16 | I24: =VLOOKUP(C9,sheet1!B9:AN48,9,FALSE) -> 20 | J24: =SUM(H24:I24) -> 36 | K24: =IF(J24>=70,"A",IF(J24>=50,"C",IF(J24>=40,"P","F"))) -> F
A25: CULTURAL & CREATIVE ART | H25: =VLOOKUP(C9,sheet1!B9:AN48,10,FALSE) -> 20 | I25: =VLOOKUP(C9,sheet1!B9:AN48,11,FALSE) -> 35 | J25: =SUM(H25:I25) -> 55 | K25: =IF(J25>=70,"A",IF(J25>=50,"C",IF(J25>=40,"P","F"))) -> C
A26: CIVIC EDUCATION | H26: =VLOOKUP(C9,sheet1!B9:AN48,12,FALSE) -> 22 | I26: =VLOOKUP(C9,sheet1!B9:AN48,13,FALSE) -> 33 | J26: =SUM(H26:I26) -> 55 | K26: =IF(J26>=70,"A",IF(J26>=50,"C",IF(J26>=40,"P","F"))) -> C
A27: CHRISTIAN RELIGIOUS STUDIES | H27: =VLOOKUP(C9,sheet1!B9:AN48,14,FALSE) -> 24 | I27: =VLOOKUP(C9,sheet1!B9:AN48,15,FALSE) -> 55 | J27: =SUM(H27:I27) -> 79 | K27: =IF(J27>=70,"A",IF(J27>=50,"C",IF(J27>=40,"P","F"))) -> A
A28: ENGLISH LANGUAGE | H28: =VLOOKUP(C9,sheet1!B9:AN48,16,FALSE) -> 24 | I28: =VLOOKUP(C9,sheet1!B9:AN48,17,FALSE) -> 41 | J28: =SUM(H28:I28) -> 65 | K28: =IF(J28>=70,"A",IF(J28>=50,"C",IF(J28>=40,"P","F"))) -> C
A29: ENGLISH PHONETICS | H29: =VLOOKUP(C9,sheet1!B9:AN48,18,FALSE) -> 0 | I29: =VLOOKUP(C9,sheet1!B9:AN48,19,FALSE) -> 0 | J29: =SUM(H29:I29) -> 0 | K29: =IF(J29>=70,"A",IF(J29>=50,"C",IF(J29>=40,"P","F"))) -> F
A30: FRENCH | H30: =VLOOKUP(C9,sheet1!B9:AN48,20,FALSE) -> 22 | I30: =VLOOKUP(C9,sheet1!B9:AN48,21,FALSE) -> 56 | J30: =SUM(H30:I30) -> 78 | K30: =IF(J30>=70,"A",IF(J30>=50,"C",IF(J30>=40,"P","F"))) -> A
A31: HISTORY | H31: =VLOOKUP(C9,sheet1!B9:AN48,22,FALSE) -> 29 | I31: =VLOOKUP(C9,sheet1!B9:AN48,23,FALSE) -> 57 | J31: =SUM(H31:I31) -> 86 | K31: =IF(J31>=70,"A",IF(J31>=50,"C",IF(J31>=40,"P","F"))) -> A
A32: HOME ECONOMICS | H32: =VLOOKUP(C9,sheet1!B9:AN48,24,FALSE) -> 27 | I32: =VLOOKUP(C9,sheet1!B9:AN48,25,FALSE) -> 53 | J32: =SUM(H32:I32) -> 80 | K32: =IF(J32>=70,"A",IF(J32>=50,"C",IF(J32>=40,"P","F"))) -> A
A33: IGBO LANGUAGE | H33: =VLOOKUP(C9,sheet1!B9:AN48,26,FALSE) -> 0 | I33: =VLOOKUP(C9,sheet1!B9:AN48,27,FALSE) -> 0 | J33: =SUM(H33:I33) -> 0 | K33: =IF(J33>=70,"A",IF(J33>=50,"C",IF(J33>=40,"P","F"))) -> F
A34: INFORMATION TECHNOLOGY | H34: =VLOOKUP(C9,sheet1!B9:AN48,28,FALSE) -> 24 | I34: =VLOOKUP(C9,sheet1!B9:AN48,29,FALSE) -> 39 | J34: =SUM(H34:I34) -> 63 | K34: =IF(J34>=70,"A",IF(J34>=50,"C",IF(J34>=40,"P","F"))) -> C
A35: MATHEMATICS | H35: =VLOOKUP(C9,sheet1!B9:AN48,30,FALSE) -> 25 | I35: =VLOOKUP(C9,sheet1!B9:AN48,31,FALSE) -> 40 | J35: =SUM(H35:I35) -> 65 | K35: =IF(J35>=70,"A",IF(J35>=50,"C",IF(J35>=40,"P","F"))) -> C
A36: PHYSICAL & HEALTH EDUCATION | H36: =VLOOKUP(C9,sheet1!B9:AN48,32,FALSE) -> 26 | I36: =VLOOKUP(C9,sheet1!B9:AN48,33,FALSE) -> 37 | J36: =SUM(H36:I36) -> 63 | K36: =IF(J36>=70,"A",IF(J36>=50,"C",IF(J36>=40,"P","F"))) -> C
A37: SECURITY EDUCATION | H37: =VLOOKUP(C9,sheet1!B9:AN48,34,FALSE) -> 21 | I37: =VLOOKUP(C9,sheet1!B9:AN48,35,FALSE) -> 33 | J37: =SUM(H37:I37) -> 54 | K37: =IF(J37>=70,"A",IF(J37>=50,"C",IF(J37>=40,"P","F"))) -> C
A38: SOCIAL STUDIES | H38: =VLOOKUP(C9,sheet1!B9:AN48,36,FALSE) -> 22 | I38: =VLOOKUP(C9,sheet1!B9:AN48,37,FALSE) -> 53 | J38: =SUM(H38:I38) -> 75 | K38: =IF(J38>=70,"A",IF(J38>=50,"C",IF(J38>=40,"P","F"))) -> A
A39: YORUBA LANGUAGE | H39: =VLOOKUP(C9,sheet1!B9:AN48,38,FALSE) -> 23 | I39: =VLOOKUP(C9,sheet1!B9:AN48,39,FALSE) -> 68 | J39: =SUM(H39:I39) -> 91 | K39: =IF(J39>=70,"A",IF(J39>=50,"C",IF(J39>=40,"P","F"))) -> A
G45: SIGNATURE & STAMP
A46: CLASS TEACHER'S REMARK:
A47: She tries her best but needs to put in more effort in her weak subjects.
A49: PRINCIPAL'S COMMENT:
A50: Very good result. Keep it up. Promoted to the Next Class.
A53: KEYS TO GRADE:
...

Sheet sheet8
B1: EASYNETT INT'L COLLEGE OF TECH.
B3: 76, WILMER CRESCENT, OLODI-APAPA, LAGOS
B4: TEL: 07030903097, 08054260717
B5: REPORT CARD
J7: PASSPORT PHOTO
A9: Student Name: | C9: =(sheet1!B14) -> CHIEKEZIE MAXWELL
A10: Class: | C10: =(sheet1!B7) -> JSS 1A
A11: Session: | C11: =(sheet1!C4) -> 2025/2026
A12: Term: | C12: =(sheet1!B5) -> FIRST TERM | F12: Average Score: | H12: =VLOOKUP(C9,sheet2!B8:E47,3,FALSE) -> 34.823529
A13: Next Term Begins: | C13: =(sheet2!E6) -> 12TH JANUARY 2026 | F13: Position: | H13: =VLOOKUP(C9,sheet2!B8:E47,4,FALSE) -> 20th
A15: FREQUENCIES | D15: SCHOOL ATTENDANCE | G15: PSYCHOMOTOR | H15: PUNCTUALITY | J15: B
A16: No. of times School Opened: | D16: =(sheet2!C6) -> 128 | H16: NEATNESS | J16: C
A17: No. of times Present: | D17: =VLOOKUP(C9,sheet2!B8:C47,2,FALSE) -> 116 | H17: HONESTY | J17: B
A18: No. in Class: | D18: =(sheet2!D6) -> 22 | H18: CREATIVITY | J18: D
A20: SUBJECT | H20: CA | I20: EXAM | J20: TOTAL | K20: GRADE
A21: AGRICULTURAL SCIENCE | H21: =VLOOKUP(C9,sheet1!B9:AN48,2,FALSE) -> 28 | I21: =VLOOKUP(C9,sheet1!B9:AN48,3,FALSE) -> 18 | J21: =SUM(H21:I21) -> 46 | K21: =IF(J21>=70,"A",IF(J21>=50,"C",IF(J21>=40,"P","F"))) -> P
A22: BASIC SCIENCE | H22: =VLOOKUP(C9,sheet1!B9:AN48,4,FALSE) -> 22 | I22: =VLOOKUP(C9,sheet1!B9:AN48,5,FALSE) -> 21 | J22: =SUM(H22:I22) -> 43 | K22: =IF(J22>=70,"A",IF(J22>=50,"C",IF(J22>=40,"P","F"))) -> P
A23: BASIC TECH | H23: =VLOOKUP(C9,sheet1!B9:AN48,6,FALSE) -> 20 | I23: =VLOOKUP(C9,sheet1!B9:AN48,7,FALSE) -> 5 | J23: =SUM(H23:I23) -> 25 | K23: =IF(J23>=70,"A",IF(J23>=50,"C",IF(J23>=40,"P","F"))) -> F
A24: BUSINESS STUDIES | H24: =VLOOKUP(C9,sheet1!B9:AN48,8,FALSE) -> 16 | I24: =VLOOKUP(C9,sheet1!B9:AN48,9,FALSE) -> 32 | J24: =SUM(H24:I24) -> 48 | K24: =IF(J24>=70,"A",IF(J24>=50,"C",IF(J24>=40,"P","F"))) -> P
A25: CULTURAL & CREATIVE ART | H25: =VLOOKUP(C9,sheet1!B9:AN48,10,FALSE) -> 20 | I25: =VLOOKUP(C9,sheet1!B9:AN48,11,FALSE) -> 20 | J25: =SUM(H25:I25) -> 40 | K25: =IF(J25>=70,"A",IF(J25>=50,"C",IF(J25>=40,"P","F"))) -> P
A26: CIVIC EDUCATION | H26: =VLOOKUP(C9,sheet1!B9:AN48,12,FALSE) -> 14 | I26: =VLOOKUP(C9,sheet1!B9:AN48,13,FALSE) -> 22 | J26: =SUM(H26:I26) -> 36 | K26: =IF(J26>=70,"A",IF(J26>=50,"C",IF(J26>=40,"P","F"))) -> F
A27: CHRISTIAN RELIGIOUS STUDIES | H27: =VLOOKUP(C9,sheet1!B9:AN48,14,FALSE) -> 17 | I27: =VLOOKUP(C9,sheet1!B9:AN48,15,FALSE) -> 13 | J27: =SUM(H27:I27) -> 30 | K27: =IF(J27>=70,"A",IF(J27>=50,"C",IF(J27>=40,"P","F"))) -> F
A28: ENGLISH LANGUAGE | H28: =VLOOKUP(C9,sheet1!B9:AN48,16,FALSE) -> 18 | I28: =VLOOKUP(C9,sheet1!B9:AN48,17,FALSE) -> 14 | J28: =SUM(H28:I28) -> 32 | K28: =IF(J28>=70,"A",IF(J28>=50,"C",IF(J28>=40,"P","F"))) -> F
A29: ENGLISH PHONETICS | H29: =VLOOKUP(C9,sheet1!B9:AN48,18,FALSE) -> 0 | I29: =VLOOKUP(C9,sheet1!B9:AN48,19,FALSE) -> 0 | J29: =SUM(H29:I29) -> 0 | K29: =IF(J29>=70,"A",IF(J29>=50,"C",IF(J29>=40,"P","F"))) -> F
A30: FRENCH | H30: =VLOOKUP(C9,sheet1!B9:AN48,20,FALSE) -> 18 | I30: =VLOOKUP(C9,sheet1!B9:AN48,21,FALSE) -> 1 | J30: =SUM(H30:I30) -> 19 | K30: =IF(J30>=70,"A",IF(J30>=50,"C",IF(J30>=40,"P","F"))) -> F
A31: HISTORY | H31: =VLOOKUP(C9,sheet1!B9:AN48,22,FALSE) -> 17 | I31: =VLOOKUP(C9,sheet1!B9:AN48,23,FALSE) -> 24 | J31: =SUM(H31:I31) -> 41 | K31: =IF(J31>=70,"A",IF(J31>=50,"C",IF(J31>=40,"P","F"))) -> P
A32: HOME ECONOMICS | H32: =VLOOKUP(C9,sheet1!B9:AN48,24,FALSE) -> 20 | I32: =VLOOKUP(C9,sheet1!B9:AN48,25,FALSE) -> 20 | J32: =SUM(H32:I32) -> 40 | K32: =IF(J32>=70,"A",IF(J32>=50,"C",IF(J32>=40,"P","F"))) -> P
A33: IGBO LANGUAGE | H33: =VLOOKUP(C9,sheet1!B9:AN48,26,FALSE) -> 0 | I33: =VLOOKUP(C9,sheet1!B9:AN48,27,FALSE) -> 0 | J33: =SUM(H33:I33) -> 0 | K33: =IF(J33>=70,"A",IF(J33>=50,"C",IF(J33>=40,"P","F"))) -> F
A34: INFORMATION TECHNOLOGY | H34: =VLOOKUP(C9,sheet1!B9:AN48,28,FALSE) -> 18 | I34: =VLOOKUP(C9,sheet1!B9:AN48,29,FALSE) -> 25 | J34: =SUM(H34:I34) -> 43 | K34: =IF(J34>=70,"A",IF(J34>=50,"C",IF(J34>=40,"P","F"))) -> P
A35: MATHEMATICS | H35: =VLOOKUP(C9,sheet1!B9:AN48,30,FALSE) -> 20 | I35: =VLOOKUP(C9,sheet1!B9:AN48,31,FALSE) -> 18 | J35: =SUM(H35:I35) -> 38 | K35: =IF(J35>=70,"A",IF(J35>=50,"C",IF(J35>=40,"P","F"))) -> F
A36: PHYSICAL & HEALTH EDUCATION | H36: =VLOOKUP(C9,sheet1!B9:AN48,32,FALSE) -> 29 | I36: =VLOOKUP(C9,sheet1!B9:AN48,33,FALSE) -> 7 | J36: =SUM(H36:I36) -> 36 | K36: =IF(J36>=70,"A",IF(J36>=50,"C",IF(J36>=40,"P","F"))) -> F
A37: SECURITY EDUCATION | H37: =VLOOKUP(C9,sheet1!B9:AN48,34,FALSE) -> 14 | I37: =VLOOKUP(C9,sheet1!B9:AN48,35,FALSE) -> 5 | J37: =SUM(H37:I37) -> 19 | K37: =IF(J37>=70,"A",IF(J37>=50,"C",IF(J37>=40,"P","F"))) -> F
A38: SOCIAL STUDIES | H38: =VLOOKUP(C9,sheet1!B9:AN48,36,FALSE) -> 20 | I38: =VLOOKUP(C9,sheet1!B9:AN48,37,FALSE) -> 17 | J38: =SUM(H38:I38) -> 37 | K38: =IF(J38>=70,"A",IF(J38>=50,"C",IF(J38>=40,"P","F"))) -> F
A39: YORUBA LANGUAGE | H39: =VLOOKUP(C9,sheet1!B9:AN48,38,FALSE) -> 12 | I39: =VLOOKUP(C9,sheet1!B9:AN48,39,FALSE) -> 7 | J39: =SUM(H39:I39) -> 19 | K39: =IF(J39>=70,"A",IF(J39>=50,"C",IF(J39>=40,"P","F"))) -> F
G45: SIGNATURE & STAMP
A46: CLASS TEACHER'S REMARK:
A47: He needs to pay more attention in class to improve his understanding.
A49: PRINCIPAL'S COMMENT:
A50: Poor result. You can do better next term
A53: KEYS TO GRADE:
...

Sheet sheet9
B1: EASYNETT INT'L COLLEGE OF TECH.
B3: 76, WILMER CRESCENT, OLODI-APAPA, LAGOS
B4: TEL: 07030903097, 08054260717
B5: REPORT CARD
J7: PASSPORT PHOTO
A9: Student Name: | C9: =(sheet1!B15) -> EDET MOSES
A10: Class: | C10: =(sheet1!B7) -> JSS 1A
A11: Session: | C11: =(sheet1!C4) -> 2025/2026
A12: Term: | C12: =(sheet1!B5) -> FIRST TERM | F12: Average Score: | H12: =VLOOKUP(C9,sheet2!B8:E47,3,FALSE) -> 55.058824
A13: Next Term Begins: | C13: =(sheet2!E6) -> 12TH JANUARY 2026 | F13: Position: | H13: =VLOOKUP(C9,sheet2!B8:E47,4,FALSE) -> 9th
A15: FREQUENCIES | D15: SCHOOL ATTENDANCE | G15: PSYCHOMOTOR | H15: PUNCTUALITY | J15: A
A16: No. of times School Opened: | D16: =(sheet2!C6) -> 128 | H16: NEATNESS | J16: B
A17: No. of times Present: | D17: =VLOOKUP(C9,sheet2!B8:C47,2,FALSE) -> 112 | H17: HONESTY | J17: A
A18: No. in Class: | D18: =(sheet2!D6) -> 22 | H18: CREATIVITY | J18: B
A20: SUBJECT | H20: CA | I20: EXAM | J20: TOTAL | K20: GRADE
A21: AGRICULTURAL SCIENCE | H21: =VLOOKUP(C9,sheet1!B9:AN48,2,FALSE) -> 28 | I21: =VLOOKUP(C9,sheet1!B9:AN48,3,FALSE) -> 30 | J21: =SUM(H21:I21) -> 58 | K21: =IF(J21>=70,"A",IF(J21>=50,"C",IF(J21>=40,"P","F"))) -> C
A22: BASIC SCIENCE | H22: =VLOOKUP(C9,sheet1!B9:AN48,4,FALSE) -> 25 | I22: =VLOOKUP(C9,sheet1!B9:AN48,5,FALSE) -> 37 | J22: =SUM(H22:I22) -> 62 | K22: =IF(J22>=70,"A",IF(J22>=50,"C",IF(J22>=40,"P","F"))) -> C
A23: BASIC TECH | H23: =VLOOKUP(C9,sheet1!B9:AN48,6,FALSE) -> 25 | I23: =VLOOKUP(C9,sheet1!B9:AN48,7,FALSE) -> 42 | J23: =SUM(H23:I23) -> 67 | K23: =IF(J23>=70,"A",IF(J23>=50,"C",IF(J23>=40,"P","F"))) -> C
A24: BUSINESS STUDIES | H24: =VLOOKUP(C9,sheet1!B9:AN48,8,FALSE) -> 14 | I24: =VLOOKUP(C9,sheet1!B9:AN48,9,FALSE) -> 42 | J24: =SUM(H24:I24) -> 56 | K24: =IF(J24>=70,"A",IF(J24>=50,"C",IF(J24>=40,"P","F"))) -> C
A25: CULTURAL & CREATIVE ART | H25: =VLOOKUP(C9,sheet1!B9:AN48,10,FALSE) -> 27 | I25: =VLOOKUP(C9,sheet1!B9:AN48,11,FALSE) -> 40 | J25: =SUM(H25:I25) -> 67 | K25: =IF(J25>=70,"A",IF(J25>=50,"C",IF(J25>=40,"P","F"))) -> C
A26: CIVIC EDUCATION | H26: =VLOOKUP(C9,sheet1!B9:AN48,12,FALSE) -> 20 | I26: =VLOOKUP(C9,sheet1!B9:AN48,13,FALSE) -> 22 | J26: =SUM(H26:I26) -> 42 | K26: =IF(J26>=70,"A",IF(J26>=50,"C",IF(J26>=40,"P","F"))) -> P
A27: CHRISTIAN RELIGIOUS STUDIES | H27: =VLOOKUP(C9,sheet1!B9:AN48,14,FALSE) -> 18 | I27: =VLOOKUP(C9,sheet1!B9:AN48,15,FALSE) -> 45 | J27: =SUM(H27:I27) -> 63 | K27: =IF(J27>=70,"A",IF(J27>=50,"C",IF(J27>=40,"P","F"))) -> C
A28: ENGLISH LANGUAGE | H28: =VLOOKUP(C9,sheet1!B9:AN48,16,FALSE) -> 19 | I28: =VLOOKUP(C9,sheet1!B9:AN48,17,FALSE) -> 18 | J28: =SUM(H28:I28) -> 37 | K28: =IF(J28>=70,"A",IF(J28>=50,"C",IF(J28>=40,"P","F"))) -> F
A29: ENGLISH PHONETICS | H29: =VLOOKUP(C9,sheet1!B9:AN48,18,FALSE) -> 0 | I29: =VLOOKUP(C9,sheet1!B9:AN48,19,FALSE) -> 0 | J29: =SUM(H29:I29) -> 0 | K29: =IF(J29>=70,"A",IF(J29>=50,"C",IF(J29>=40,"P","F"))) -> F
A30: FRENCH | H30: =VLOOKUP(C9,sheet1!B9:AN48,20,FALSE) -> 11 | I30: =VLOOKUP(C9,sheet1!B9:AN48,21,FALSE) -> 41 | J30: =SUM(H30:I30) -> 52 | K30: =IF(J30>=70,"A",IF(J30>=50,"C",IF(J30>=40,"P","F"))) -> C
A31: HISTORY | H31: =VLOOKUP(C9,sheet1!B9:AN48,22,FALSE) -> 23 | I31: =VLOOKUP(C9,sheet1!B9:AN48,23,FALSE) -> 41 | J31: =SUM(H31:I31) -> 64 | K31: =IF(J31>=70,"A",IF(J31>=50,"C",IF(J31>=40,"P","F"))) -> C
A32: HOME ECONOMICS | H32: =VLOOKUP(C9,sheet1!B9:AN48,24,FALSE) -> 27 | I32: =VLOOKUP(C9,sheet1!B9:AN48,25,FALSE) -> 43 | J32: =SUM(H32:I32) -> 70 | K32: =IF(J32>=70,"A",IF(J32>=50,"C",IF(J32>=40,"P","F"))) -> A
A33: IGBO LANGUAGE | H33: =VLOOKUP(C9,sheet1!B9:AN48,26,FALSE) -> 0 | I33: =VLOOKUP(C9,sheet1!B9:AN48,27,FALSE) -> 0 | J33: =SUM(H33:I33) -> 0 | K33: =IF(J33>=70,"A",IF(J33>=50,"C",IF(J33>=40,"P","F"))) -> F
A34: INFORMATION TECHNOLOGY | H34: =VLOOKUP(C9,sheet1!B9:AN48,28,FALSE) -> 17 | I34: =VLOOKUP(C9,sheet1!B9:AN48,29,FALSE) -> 34 | J34: =SUM(H34:I34) -> 51 | K34: =IF(J34>=70,"A",IF(J34>=50,"C",IF(J34>=40,"P","F"))) -> C
A35: MATHEMATICS | H35: =VLOOKUP(C9,sheet1!B9:AN48,30,FALSE) -> 20 | I35: =VLOOKUP(C9,sheet1!B9:AN48,31,FALSE) -> 48 | J35: =SUM(H35:I35) -> 68 | K35: =IF(J35>=70,"A",IF(J35>=50,"C",IF(J35>=40,"P","F"))) -> C
A36: PHYSICAL & HEALTH EDUCATION | H36: =VLOOKUP(C9,sheet1!B9:AN48,32,FALSE) -> 27 | I36: =VLOOKUP(C9,sheet1!B9:AN48,33,FALSE) -> 28 | J36: =SUM(H36:I36) -> 55 | K36: =IF(J36>=70,"A",IF(J36>=50,"C",IF(J36>=40,"P","F"))) -> C
A37: SECURITY EDUCATION | H37: =VLOOKUP(C9,sheet1!B9:AN48,34,FALSE) -> 15 | I37: =VLOOKUP(C9,sheet1!B9:AN48,35,FALSE) -> 38 | J37: =SUM(H37:I37) -> 53 | K37: =IF(J37>=70,"A",IF(J37>=50,"C",IF(J37>=40,"P","F"))) -> C
A38: SOCIAL STUDIES | H38: =VLOOKUP(C9,sheet1!B9:AN48,36,FALSE) -> 15 | I38: =VLOOKUP(C9,sheet1!B9:AN48,37,FALSE) -> 18 | J38: =SUM(H38:I38) -> 33 | K38: =IF(J38>=70,"A",IF(J38>=50,"C",IF(J38>=40,"P","F"))) -> F
A39: YORUBA LANGUAGE | H39: =VLOOKUP(C9,sheet1!B9:AN48,38,FALSE) -> 22 | I39: =VLOOKUP(C9,sheet1!B9:AN48,39,FALSE) -> 16 | J39: =SUM(H39:I39) -> 38 | K39: =IF(J39>=70,"A",IF(J39>=50,"C",IF(J39>=40,"P","F"))) -> F
G45: SIGNATURE & STAMP
A46: CLASS TEACHER'S REMARK:
A47: He is reliable, truthful and honest
A49: PRINCIPAL'S COMMENT:
A50: Just fair, you can do better
A53: KEYS TO GRADE:
...

Sheet sheet10
B1: EASYNETT INT'L COLLEGE OF TECH.
B3: 76, WILMER CRESCENT, OLODI-APAPA, LAGOS
B4: TEL: 07030903097, 08054260717
B5: REPORT CARD
J7: PASSPORT PHOTO
A9: Student Name: | C9: =(sheet1!B16) -> ENEJOH PHINEHAS
A10: Class: | C10: =(sheet1!B7) -> JSS 1A
A11: Session: | C11: =(sheet1!C4) -> 2025/2026
A12: Term: | C12: =(sheet1!B5) -> FIRST TERM | F12: Average Score: | H12: =VLOOKUP(C9,sheet2!B8:E47,3,FALSE) -> 39.352941
A13: Next Term Begins: | C13: =(sheet2!E6) -> 12TH JANUARY 2026 | F13: Position: | H13: =VLOOKUP(C9,sheet2!B8:E47,4,FALSE) -> 16th
A15: FREQUENCIES | D15: SCHOOL ATTENDANCE | G15: PSYCHOMOTOR | H15: PUNCTUALITY | J15: A
A16: No. of times School Opened: | D16: =(sheet2!C6) -> 128 | H16: NEATNESS | J16: B
A17: No. of times Present: | D17: =VLOOKUP(C9,sheet2!B8:C47,2,FALSE) -> 120 | H17: HONESTY | J17: A
A18: No. in Class: | D18: =(sheet2!D6) -> 22 | H18: CREATIVITY | J18: C
A20: SUBJECT | H20: CA | I20: EXAM | J20: TOTAL | K20: GRADE
A21: AGRICULTURAL SCIENCE | H21: =VLOOKUP(C9,sheet1!B9:AN48,2,FALSE) -> 28 | I21: =VLOOKUP(C9,sheet1!B9:AN48,3,FALSE) -> 39 | J21: =SUM(H21:I21) -> 67 | K21: =IF(J21>=70,"A",IF(J21>=50,"C",IF(J21>=40,"P","F"))) -> C
A22: BASIC SCIENCE | H22: =VLOOKUP(C9,sheet1!B9:AN48,4,FALSE) -> 22 | I22: =VLOOKUP(C9,sheet1!B9:AN48,5,FALSE) -> 24 | J22: =SUM(H22:I22) -> 46 | K22: =IF(J22>=70,"A",IF(J22>=50,"C",IF(J22>=40,"P","F"))) -> P
A23: BASIC TECH | H23: =VLOOKUP(C9,sheet1!B9:AN48,6,FALSE) -> 28 | I23: =VLOOKUP(C9,sheet1!B9:AN48,7,FALSE) -> 4 | J23: =SUM(H23:I23) -> 32 | K23: =IF(J23>=70,"A",IF(J23>=50,"C",IF(J23>=40,"P","F"))) -> F
A24: BUSINESS STUDIES | H24: =VLOOKUP(C9,sheet1!B9:AN48,8,FALSE) -> 15 | I24: =VLOOKUP(C9,sheet1!B9:AN48,9,FALSE) -> 15 | J24: =SUM(H24:I24) -> 30 | K24: =IF(J24>=70,"A",IF(J24>=50,"C",IF(J24>=40,"P","F"))) -> F
A25: CULTURAL & CREATIVE ART | H25: =VLOOKUP(C9,sheet1!B9:AN48,10,FALSE) -> 20 | I25: =VLOOKUP(C9,sheet1!B9:AN48,11,FALSE) -> 20 | J25: =SUM(H25:I25) -> 40 | K25: =IF(J25>=70,"A",IF(J25>=50,"C",IF(J25>=40,"P","F"))) -> P
A26: CIVIC EDUCATION | H26: =VLOOKUP(C9,sheet1!B9:AN48,12,FALSE) -> 21 | I26: =VLOOKUP(C9,sheet1!B9:AN48,13,FALSE) -> 26 | J26: =SUM(H26:I26) -> 47 | K26: =IF(J26>=70,"A",IF(J26>=50,"C",IF(J26>=40,"P","F"))) -> P
A27: CHRISTIAN RELIGIOUS STUDIES | H27: =VLOOKUP(C9,sheet1!B9:AN48,14,FALSE) -> 18 | I27: =VLOOKUP(C9,sheet1!B9:AN48,15,FALSE) -> 16 | J27: =SUM(H27:I27) -> 34 | K27: =IF(J27>=70,"A",IF(J27>=50,"C",IF(J27>=40,"P","F"))) -> F
A28: ENGLISH LANGUAGE | H28: =VLOOKUP(C9,sheet1!B9:AN48,16,FALSE) -> 18 | I28: =VLOOKUP(C9,sheet1!B9:AN48,17,FALSE) -> 13 | J28: =SUM(H28:I28) -> 31 | K28: =IF(J28>=70,"A",IF(J28>=50,"C",IF(J28>=40,"P","F"))) -> F
A29: ENGLISH PHONETICS | H29: =VLOOKUP(C9,sheet1!B9:AN48,18,FALSE) -> 0 | I29: =VLOOKUP(C9,sheet1!B9:AN48,19,FALSE) -> 0 | J29: =SUM(H29:I29) -> 0 | K29: =IF(J29>=70,"A",IF(J29>=50,"C",IF(J29>=40,"P","F"))) -> F
A30: FRENCH | H30: =VLOOKUP(C9,sheet1!B9:AN48,20,FALSE) -> 19 | I30: =VLOOKUP(C9,sheet1!B9:AN48,21,FALSE) -> 8 | J30: =SUM(H30:I30) -> 27 | K30: =IF(J30>=70,"A",IF(J30>=50,"C",IF(J30>=40,"P","F"))) -> F
A31: HISTORY | H31: =VLOOKUP(C9,sheet1!B9:AN48,22,FALSE) -> 23 | I31: =VLOOKUP(C9,sheet1!B9:AN48,23,FALSE) -> 9 | J31: =SUM(H31:I31) -> 32 | K31: =IF(J31>=70,"A",IF(J31>=50,"C",IF(J31>=40,"P","F"))) -> F
A32: HOME ECONOMICS | H32: =VLOOKUP(C9,sheet1!B9:AN48,24,FALSE) -> 20 | I32: =VLOOKUP(C9,sheet1!B9:AN48,25,FALSE) -> 20 | J32: =SUM(H32:I32) -> 40 | K32: =IF(J32>=70,"A",IF(J32>=50,"C",IF(J32>=40,"P","F"))) -> P
A33: IGBO LANGUAGE | H33: =VLOOKUP(C9,sheet1!B9:AN48,26,FALSE) -> 0 | I33: =VLOOKUP(C9,sheet1!B9:AN48,27,FALSE) -> 0 | J33: =SUM(H33:I33) -> 0 | K33: =IF(J33>=70,"A",IF(J33>=50,"C",IF(J33>=40,"P","F"))) -> F
A34: INFORMATION TECHNOLOGY | H34: =VLOOKUP(C9,sheet1!B9:AN48,28,FALSE) -> 18 | I34: =VLOOKUP(C9,sheet1!B9:AN48,29,FALSE) -> 22 | J34: =SUM(H34:I34) -> 40 | K34: =IF(J34>=70,"A",IF(J34>=50,"C",IF(J34>=40,"P","F"))) -> P
A35: MATHEMATICS | H35: =VLOOKUP(C9,sheet1!B9:AN48,30,FALSE) -> 20 | I35: =VLOOKUP(C9,sheet1!B9:AN48,31,FALSE) -> 14 | J35: =SUM(H35:I35) -> 34 | K35: =IF(J35>=70,"A",IF(J35>=50,"C",IF(J35>=40,"P","F"))) -> F
A36: PHYSICAL & HEALTH EDUCATION | H36: =VLOOKUP(C9,sheet1!B9:AN48,32,FALSE) -> 29 | I36: =VLOOKUP(C9,sheet1!B9:AN48,33,FALSE) -> 20 | J36: =SUM(H36:I36) -> 49 | K36: =IF(J36>=70,"A",IF(J36>=50,"C",IF(J36>=40,"P","F"))) -> P
A37: SECURITY EDUCATION | H37: =VLOOKUP(C9,sheet1!B9:AN48,34,FALSE) -> 18 | I37: =VLOOKUP(C9,sheet1!B9:AN48,35,FALSE) -> 14 | J37: =SUM(H37:I37) -> 32 | K37: =IF(J37>=70,"A",IF(J37>=50,"C",IF(J37>=40,"P","F"))) -> F
A38: SOCIAL STUDIES | H38: =VLOOKUP(C9,sheet1!B9:AN48,36,FALSE) -> 23 | I38: =VLOOKUP(C9,sheet1!B9:AN48,37,FALSE) -> 25 | J38: =SUM(H38:I38) -> 48 | K38: =IF(J38>=70,"A",IF(J38>=50,"C",IF(J38>=40,"P","F"))) -> P
