Workbook

Sheet LeaderBoard

Sheet DataSet
A1: SN | B1: STUDENT NAME | C1: GENDER | D1: CLASS | E1: TERM | F1: SESSION | G1: NO OF TIMES SCHOOL OPENED | H1: NO OF TIMES PRESENT | I1: AGRICULTURAL SCIENCE | J1: BASIC SCIENCE | K1: BASIC TECH | L1: BUSINESS STUDIES | M1: CULTURAL & CREATIVE ART | N1: CIVIC EDUCATION | O1: CHRISTIAN RELIGIOUS STUDIES | P1: ENGLISH LANGUAGE | Q1: ENGLISH PHONETICS | R1: FRENCH | S1: HISTORY | T1: HOME ECONOMICS | U1: IGBO LANGUAGE | V1: INFORMATION TECHNOLOGY | W1: MATHEMATICS | X1: PHYSICAL & HEALTH EDUCATION | Y1: SECURITY EDUCATION | Z1: SOCIAL STUDIES | AA1: YORUBA LANGUAGE

Sheet Pivot Table

Sheet 1st Term
A1: EASYNETT INT'L COLLEGE OF TECH. (EICT)
A3: 76, WILMER CRESCENT, OLODI-APAPA, LAGOS
A4: SESSION | C4: 2025/2026
B5: FIRST TERM | C5: BROADSHEET | AO5: CUMMULATIVE SCORE
A7: S/NO | B7: JSS 1A | C7: AGRICULTURAL SCIENCE | E7: BASIC SCIENCE | G7: BASIC TECH | I7: BUSINESS STUDIES | K7: CULTURAL & CREATIVE ART | L7: 10 | M7: CIVIC EDUCATION | N7: 12 | O7: CHRISTIAN RELIGIOUS STUDIES | Q7: ENGLISH LANGUAGE | S7: ENGLISH PHONETICS | U7: FRENCH | W7: HISTORY | Y7: HOME ECONOMICS | AA7: IGBO LANGUAGE | AC7: INFORMATION TECHNOLOGY | AE7: MATHEMATICS | AG7: PHYSICAL & HEALTH EDUCATION | AI7: SECURITY EDUCATION | AK7: SOCIAL STUDIES | AM7: YORUBA LANGUAGE | AO7: TOTAL | AP7: AVERAGE
B8: STUDENT NAME | C8: CA | D8: EXAM | E8: CA | F8: EXAM | G8: CA | H8: EXAM | I8: CA | J8: EXAM | K8: CA | L8: EXAM | M8: CA | N8: EXAM | O8: CA | P8: EXAM | Q8: CA | R8: EXAM | S8: CA | T8: EXAM | U8: CA | V8: EXAM | W8: CA | X8: EXAM | Y8: CA | Z8: EXAM | AA8: CA | AB8: EXAM | AC8: CA | AD8: EXAM | AE8: CA | AF8: EXAM | AG8: CA | AH8: EXAM | AI8: CA | AJ8: EXAM | AK8: CA | AL8: EXAM | AM8: CA | AN8: EXAM
A9: 1 | B9: ADAKARAZA SAMUEL | C9: 28 | D9: 28 | E9: 28 | F9: 28 | G9: 17 | H9: 8 | I9: 17 | J9: 15 | K9: 13 | L9: 20 | M9: 17 | N9: 10 | O9: 21 | P9: 30 | Q9: 13 | R9: 11 | U9: 17 | V9: 6 | W9: 15 | X9: 11 | Y9: 20 | Z9: 24 | AC9: 18 | AD9: 10 | AE9: 20 | AF9: 20 | AG9: 29 | AH9: 10 | AI9: 15 | AJ9: 3 | AK9: 15 | AL9: 16 | AM9: 21 | AN9: 22 | AO9: =SUM(C9:AN9) -> 596 | AP9: =AO9/17 -> 35.058824
A10: 2 | B10: ADEOLA PEDRO | C10: 28 | D10: 39 | E10: 25 | F10: 39 | G10: 20 | H10: 22 | I10: 24 | J10: 23 | K10: 21 | L10: 20 | M10: 24 | N10: 10 | O10: 20 | P10: 30 | Q10: 24 | R10: 25 | U10: 22 | V10: 37 | W10: 28 | X10: 36 | Y10: 25 | Z10: 30 | AC10: 24 | AD10: 29 | AE10: 20 | AF10: 20 | AG10: 29 | AH10: 28 | AI10: 17 | AJ10: 4 | AK10: 14 | AL10: 22 | AM10: 27 | AN10: 40 | AO10: =SUM(C10:AN10) -> 846 | AP10: =AO10/17 -> 49.764706
A11: 3 | B11: ASAMS DANIELLA | C11: 28 | D11: 35 | E11: 25 | F11: 55 | G11: 22 | H11: 60 | I11: 18 | J11: 22 | K11: 20 | L11: 20 | M11: 17 | N11: 38 | O11: 28 | P11: 45 | Q11: 23 | R11: 52 | U11: 20 | V11: 43 | W11: 26 | X11: 35 | Y11: 25 | Z11: 31 | AC11: 18 | AD11: 37 | AE11: 20 | AF11: 30 | AG11: 26 | AH11: 32 | AI11: 20 | AJ11: 25 | AK11: 20 | AL11: 31 | AM11: 26 | AN11: 40 | AO11: =SUM(C11:AN11) -> 1013 | AP11: =AO11/17 -> 59.588235
A12: 4 | B12: ASIBOR NANCY | C12: 28 | D12: 50 | E12: 27 | F12: 51 | G12: 20 | H12: 30 | I12: 24 | J12: 30 | K12: 29 | L12: 38 | M12: 23 | N12: 53 | O12: 23 | P12: 36 | Q12: 27 | R12: 26 | U12: 10 | V12: 44 | W12: 27 | X12: 35 | Y12: 23 | Z12: 30 | AC12: 21 | AD12: 36 | AE12: 20 | AF12: 28 | AG12: 26 | AH12: 40 | AI12: 17 | AJ12: 27 | AK12: 20 | AL12: 41 | AM12: 19 | AN12: 26 | AO12: =SUM(C12:AN12) -> 1005 | AP12: =AO12/17 -> 59.117647
A13: 5 | B13: BANKOLE AMEERAT | C13: 28 | D13: 68 | E13: 28 | F13: 66 | G13: 22 | H13: 52 | I13: 16 | J13: 20 | K13: 20 | L13: 35 | M13: 22 | N13: 33 | O13: 24 | P13: 55 | Q13: 24 | R13: 41 | U13: 22 | V13: 56 | W13: 29 | X13: 57 | Y13: 27 | Z13: 53 | AC13: 24 | AD13: 39 | AE13: 25 | AF13: 40 | AG13: 26 | AH13: 37 | AI13: 21 | AJ13: 33 | AK13: 22 | AL13: 53 | AM13: 23 | AN13: 68 | AO13: =SUM(C13:AN13) -> 1209 | AP13: =AO13/17 -> 71.117647
A14: 6 | B14: CHIEKEZIE MAXWELL | C14: 28 | D14: 18 | E14: 22 | F14: 21 | G14: 20 | H14: 5 | I14: 16 | J14: 32 | K14: 20 | L14: 20 | M14: 14 | N14: 22 | O14: 17 | P14: 13 | Q14: 18 | R14: 14 | U14: 18 | V14: 1 | W14: 17 | X14: 24 | Y14: 20 | Z14: 20 | AC14: 18 | AD14: 25 | AE14: 20 | AF14: 18 | AG14: 29 | AH14: 7 | AI14: 14 | AJ14: 5 | AK14: 20 | AL14: 17 | AM14: 12 | AN14: 7 | AO14: =SUM(C14:AN14) -> 592 | AP14: =AO14/17 -> 34.823529
A15: 7 | B15: EDET MOSES | C15: 28 | D15: 30 | E15: 25 | F15: 37 | G15: 25 | H15: 42 | I15: 14 | J15: 42 | K15: 27 | L15: 40 | M15: 20 | N15: 22 | O15: 18 | P15: 45 | Q15: 19 | R15: 18 | U15: 11 | V15: 41 | W15: 23 | X15: 41 | Y15: 27 | Z15: 43 | AC15: 17 | AD15: 34 | AE15: 20 | AF15: 48 | AG15: 27 | AH15: 28 | AI15: 15 | AJ15: 38 | AK15: 15 | AL15: 18 | AM15: 22 | AN15: 16 | AO15: =SUM(C15:AN15) -> 936 | AP15: =AO15/17 -> 55.058824
A16: 8 | B16: ENEJOH PHINEHAS | C16: 28 | D16: 39 | E16: 22 | F16: 24 | G16: 28 | H16: 4 | I16: 15 | J16: 15 | K16: 20 | L16: 20 | M16: 21 | N16: 26 | O16: 18 | P16: 16 | Q16: 18 | R16: 13 | U16: 19 | V16: 8 | W16: 23 | X16: 9 | Y16: 20 | Z16: 20 | AC16: 18 | AD16: 22 | AE16: 20 | AF16: 14 | AG16: 29 | AH16: 20 | AI16: 18 | AJ16: 14 | AK16: 23 | AL16: 25 | AM16: 13 | AN16: 27 | AO16: =SUM(C16:AN16) -> 669 | AP16: =AO16/17 -> 39.352941
A17: 9 | B17: EWELUKWA FAVOUR | C17: 28 | D17: 63 | E17: 27 | F17: 53 | G17: 27 | H17: 46 | I17: 20 | J17: 40 | K17: 26 | L17: 30 | M17: 17 | N17: 16 | O17: 21 | P17: 49 | Q17: 28 | R17: 40 | U17: 20 | V17: 50 | W17: 30 | X17: 54 | Y17: 29 | Z17: 53 | AC17: 23 | AD17: 38 | AE17: 20 | AF17: 25 | AG17: 26 | AH17: 35 | AI17: 19 | AJ17: 24 | AK17: 23 | AL17: 35 | AM17: 24 | AN17: 14 | AO17: =SUM(C17:AN17) -> 1073 | AP17: =AO17/17 -> 63.117647
A18: 10 | B18: HAMMED OLAMIDE | C18: 28 | D18: 5 | E18: 17 | F18: 5 | G18: 26 | H18: 5 | I18: 14 | J18: 15 | K18: 10 | L18: 20 | M18: 14 | N18: 10 | O18: 18 | P18: 16 | Q18: 17 | R18: 9 | U18: 15 | V18: 2 | W18: 17 | X18: 1 | Y18: 20 | Z18: 20 | AC18: 11 | AD18: 2 | AE18: 15 | AF18: 5 | AG18: 30 | AH18: 1 | AI18: 12 | AJ18: 5 | AK18: 8 | AL18: 9 | AM18: 9 | AN18: 1 | AO18: =SUM(C18:AN18) -> 412 | AP18: =AO18/17 -> 24.235294
A19: 11 | B19: HAMZAT AKOREDE | C19: 28 | D19: 27 | E19: 18 | F19: 2 | G19: 25 | H19: 18 | I19: 14 | J19: 15 | K19: 20 | L19: 20 | M19: 18 | N19: 10 | O19: 18 | P19: 11 | Q19: 18 | R19: 15 | U19: 17 | V19: 7 | W19: 22 | X19: 15 | Y19: 20 | Z19: 25 | AC19: 14 | AD19: 12 | AE19: 18 | AF19: 5 | AG19: 30 | AH19: 7 | AI19: 15 | AJ19: 5 | AK19: 20 | AL19: 15 | AM19: 19 | AN19: 27 | AO19: =SUM(C19:AN19) -> 570 | AP19: =AO19/17 -> 33.529412
A20: 12 | B20: JAMES DIVINE | C20: 28 | D20: 28 | E20: 19 | F20: 14 | G20: 27 | H20: 7 | I20: 16 | J20: 24 | K20: 20 | L20: 20 | M20: 19 | N20: 12 | O20: 18 | P20: 24 | Q20: 21 | R20: 10 | U20: 16 | V20: 4 | W20: 21 | X20: 13 | Y20: 25 | Z20: 25 | AC20: 14 | AD20: 23 | AE20: 18 | AF20: 18 | AG20: 30 | AH20: 10 | AI20: 16 | AJ20: 7 | AK20: 22 | AL20: 23 | AM20: 14 | AN20: 38 | AO20: =SUM(C20:AN20) -> 644 | AP20: =AO20/17 -> 37.882353
... A30: 22 | B30: WASIU NIMOTALLAH | C30: 28 | D30: 28 | E30: 28 | F30: 28 | G30: 28 | H30: 43 | I30: 17 | J30: 16 | K30: 24 | L30: 30 | M30: 17 | N30: 29 | O30: 21 | P30: 20 | Q30: 21 | R30: 15 | U30: 30 | V30: 38 | W30: 23 | X30: 27 | Y30: 20 | Z30: 20 | AC30: 17 | AD30: 22 | AE30: 21 | AF30: 40 | AG30: 26 | AH30: 20 | AI30: 21 | AJ30: 8 | AK30: 19 | AL30: 14 | AM30: 21 | AN30: 60 | AO30: =SUM(C30:AN30) -> 840 | AP30: =AO30/17 -> 49.411765
A31: 23 | AO31: =SUM(C31:AN31) -> 0 | AP31: =AO31/17 -> 0
A32: 24 | AO32: =SUM(C32:AN32) -> 0 | AP32: =AO32/17 -> 0
A33: 25 | AO33: =SUM(C33:AN33) -> 0 | AP33: =AO33/17 -> 0
A34: 26 | AO34: =SUM(C34:AN34) -> 0 | AP34: =AO34/17 -> 0
A35: 27 | AO35: =SUM(C35:AN35) -> 0 | AP35: =AO35/17 -> 0
A36: 28 | AO36: =SUM(C36:AN36) -> 0 | AP36: =AO36/17 -> 0
A37: 29 | AO37: =SUM(C37:AN37) -> 0 | AP37: =AO37/17 -> 0
A38: 30 | AO38: =SUM(C38:AN38) -> 0 | AP38: =AO38/17 -> 0
A39: 31 | AO39: =SUM(C39:AN39) -> 0 | AP39: =AO39/17 -> 0
A40: 32 | AO40: =SUM(C40:AN40) -> 0 | AP40: =AO40/17 -> 0
A41: 33 | AO41: =SUM(C41:AN41) -> 0 | AP41: =AO41/17 -> 0
A42: 34 | AO42: =SUM(C42:AN42) -> 0 | AP42: =AO42/17 -> 0
... A48: 40 | AO48: =SUM(C48:AN48) -> 0 | AP48: =AO48/17 -> 0

Sheet 2nd Term
A1: EASYNETT INT'L COLLEGE OF TECH. (EICT)
A3: 76, WILMER CRESCENT, OLODI-APAPA, LAGOS
A4: SESSION | C4: 2025/2026
B5: SECOND TERM | C5: BROADSHEET | AO5: CUMMULATIVE SCORE
A7: S/NO | B7: JSS 1A | C7: AGRICULTURAL SCIENCE | E7: BASIC SCIENCE | G7: BASIC TECH | I7: BUSINESS STUDIES | K7: CULTURAL & CREATIVE ART | L7: 10 | M7: CIVIC EDUCATION | N7: 12 | O7: CHRISTIAN RELIGIOUS STUDIES | Q7: ENGLISH LANGUAGE | S7: ENGLISH PHONETICS | U7: FRENCH | W7: HISTORY | Y7: HOME ECONOMICS | AA7: IGBO LANGUAGE | AC7: INFORMATION TECHNOLOGY | AE7: MATHEMATICS | AG7: PHYSICAL & HEALTH EDUCATION | AI7: SECURITY EDUCATION | AK7: SOCIAL STUDIES | AM7: YORUBA LANGUAGE | AO7: TOTAL | AP7: AVERAGE
B8: STUDENT NAME | C8: CA | D8: EXAM | E8: CA | F8: EXAM | G8: CA | H8: EXAM | I8: CA | J8: EXAM | K8: CA | L8: EXAM | M8: CA | N8: EXAM | O8: CA | P8: EXAM | Q8: CA | R8: EXAM | S8: CA | T8: EXAM | U8: CA | V8: EXAM | W8: CA | X8: EXAM | Y8: CA | Z8: EXAM | AA8: CA | AB8: EXAM | AC8: CA | AD8: EXAM | AE8: CA | AF8: EXAM | AG8: CA | AH8: EXAM | AI8: CA | AJ8: EXAM | AK8: CA | AL8: EXAM | AM8: CA | AN8: EXAM
A9: 1 | B9: =('1st Term'!B9) -> ADAKARAZA SAMUEL | C9: 28 | D9: 28 | E9: 17 | F9: 31 | G9: 14 | H9: 26 | I9: 15 | J9: 25 | K9: 13 | L9: 20 | M9: 14 | N9: 16 | O9: 21 | P9: 27 | Q9: 14 | R9: 26 | U9: 17 | V9: 41 | W9: 16 | X9: 21 | Y9: 17 | Z9: 20 | AC9: 12 | AD9: 13 | AE9: 20 | AF9: 30 | AG9: 29 | AH9: 10 | AI9: 12 | AJ9: 19 | AK9: 14 | AL9: 25 | AM9: 17 | AN9: 22 | AO9: =SUM(C9:AN9) -> 690 | AP9: =AO9/17 -> 40.588235
A10: 2 | B10: =('1st Term'!B10) -> ADEOLA PEDRO | C10: 28 | D10: 39 | E10: 27 | F10: 50 | G10: 24 | H10: 30 | I10: 17 | J10: 25 | K10: 20 | L10: 30 | M10: 18 | N10: 33 | O10: 24 | P10: 39 | Q10: 18 | R10: 44 | U10: 16 | V10: 51 | W10: 24 | X10: 50 | Y10: 21 | Z10: 39 | AC10: 22 | AD10: 42 | AE10: 20 | AF10: 45 | AG10: 29 | AH10: 32 | AI10: 27 | AJ10: 27 | AK10: 21 | AL10: 34 | AM10: 26 | AN10: 50 | AO10: =SUM(C10:AN10) -> 1042 | AP10: =AO10/17 -> 61.294118
A11: 3 | B11: =('1st Term'!B11) -> ASAMS DANIELLA | C11: 28 | D11: 40 | E11: 29 | F11: 52 | G11: 24 | H11: 67 | I11: 19 | J11: 41 | K11: 30 | L11: 40 | M11: 20 | N11: 31 | O11: 22 | P11: 34 | Q11: 29 | R11: 43 | U11: 21 | V11: 49 | W11: 28 | X11: 57 | Y11: 20 | Z11: 30 | AC11: 16 | AD11: 38 | AE11: 15 | AF11: 31 | AG11: 26 | AH11: 35 | AI11: 22 | AJ11: 40 | AK11: 22 | AL11: 50 | AM11: 24 | AN11: 43 | AO11: =SUM(C11:AN11) -> 1116 | AP11: =AO11/17 -> 65.647059
A12: 4 | B12: =('1st Term'!B12) -> ASIBOR NANCY | C12: 28 | D12: 55 | E12: 28 | F12: 65 | G12: 30 | H12: 57 | I12: 21 | J12: 37 | K12: 30 | L12: 44 | M12: 22 | N12: 40 | O12: 27 | P12: 34 | Q12: 27 | R12: 53 | U12: 23 | V12: 57 | W12: 29 | X12: 44 | Y12: 23 | Z12: 35 | AC12: 28 | AD12: 42 | AE12: 15 | AF12: 60 | AG12: 26 | AH12: 45 | AI12: 29 | AJ12: 47 | AK12: 22 | AL12: 60 | AM12: 26 | AN12: 48 | AO12: =SUM(C12:AN12) -> 1257 | AP12: =AO12/17 -> 73.941176
A13: 5 | B13: =('1st Term'!B13) -> BANKOLE AMEERAT | C13: 30 | D13: 68 | E13: 30 | F13: 65 | G13: 30 | H13: 67 | I13: 19 | J13: 35 | K13: 30 | L13: 63 | M13: 18 | N13: 35 | O13: 26 | P13: 41 | Q13: 29 | R13: 57 | U13: 24 | V13: 61 | W13: 29 | X13: 61 | Y13: 25 | Z13: 55 | AC13: 30 | AD13: 51 | AE13: 30 | AF13: 65 | AG13: 26 | AH13: 50 | AI13: 22 | AJ13: 52 | AK13: 27 | AL13: 53 | AM13: 26 | AN13: 68 | AO13: =SUM(C13:AN13) -> 1398 | AP13: =AO13/17 -> 82.235294
A14: 6 | B14: =('1st Term'!B14) -> CHIEKEZIE MAXWELL | C14: 28 | D14: 18 | E14: 15 | F14: 22 | G14: 18 | H14: 27 | I14: 15 | J14: 20 | K14: 24 | L14: 28 | M14: 15 | N14: 17 | O14: 19 | P14: 22 | Q14: 16 | R14: 21 | U14: 13 | V14: 25 | W14: 21 | X14: 32 | Y14: 18 | Z14: 15 | AC14: 12 | AD14: 17 | AE14: 20 | AF14: 13 | AG14: 29 | AH14: 30 | AI14: 14 | AJ14: 14 | AK14: 14 | AL14: 28 | AM14: 11 | AN14: 15 | AO14: =SUM(C14:AN14) -> 666 | AP14: =AO14/17 -> 39.176471
A15: 7 | B15: =('1st Term'!B15) -> EDET MOSES | C15: 28 | D15: 35 | E15: 25 | F15: 41 | G15: 17 | H15: 37 | I15: 17 | J15: 19 | K15: 16 | L15: 25 | M15: 21 | N15: 20 | O15: 19 | P15: 34 | Q15: 26 | R15: 35 | U15: 22 | V15: 42 | W15: 30 | X15: 37 | Y15: 23 | Z15: 27 | AC15: 16 | AD15: 21 | AE15: 25 | AF15: 11 | AG15: 27 | AH15: 30 | AI15: 15 | AJ15: 26 | AK15: 17 | AL15: 30 | AM15: 22 | AN15: 20 | AO15: =SUM(C15:AN15) -> 856 | AP15: =AO15/17 -> 50.352941
A16: 8 | B16: =('1st Term'!B16) -> ENEJOH PHINEHAS | C16: 28 | D16: 42 | E16: 19 | F16: 36 | G16: 24 | H16: 47 | I16: 17 | J16: 25 | K16: 29 | L16: 20 | M16: 19 | N16: 16 | O16: 25 | P16: 27 | Q16: 18 | R16: 20 | U16: 14 | V16: 28 | W16: 24 | X16: 22 | Y16: 16 | Z16: 15 | AC16: 12 | AD16: 19 | AE16: 25 | AF16: 29 | AG16: 29 | AH16: 30 | AI16: 18 | AJ16: 22 | AK16: 16 | AL16: 36 | AM16: 21 | AN16: 15 | AO16: =SUM(C16:AN16) -> 803 | AP16: =AO16/17 -> 47.235294
A17: 9 | B17: =('1st Term'!B17) -> EWELUKWA FAVOUR | C17: 29 | D17: 65 | E17: 26 | F17: 58 | G17: 26 | H17: 70 | I17: 18 | J17: 26 | K17: 30 | L17: 59 | M17: 20 | N17: 34 | O17: 25 | P17: 42 | Q17: 22 | R17: 48 | U17: 24 | V17: 59 | W17: 29 | X17: 62 | Y17: 21 | Z17: 36 | AC17: 20 | AD17: 41 | AE17: 25 | AF17: 52 | AG17: 26 | AH17: 40 | AI17: 17 | AJ17: 24 | AK17: 18 | AL17: 60 | AM17: 18 | AN17: 50 | AO17: =SUM(C17:AN17) -> 1220 | AP17: =AO17/17 -> 71.764706
A18: 10 | B18: =('1st Term'!B18) -> HAMMED OLAMIDE | C18: 28 | D18: 5 | E18: 12 | F18: 11 | G18: 16 | H18: 13 | I18: 14 | J18: 7 | K18: 12 | L18: 27 | M18: 10 | N18: 15 | O18: 18 | P18: 20 | Q18: 13 | R18: 20 | U18: 11 | V18: 3 | W18: 11 | X18: 14 | Y18: 15 | Z18: 15 | AC18: 12 | AD18: 3 | AE18: 25 | AF18: 15 | AG18: 30 | AH18: 20 | AI18: 23 | AJ18: 55 | AK18: 14 | AL18: 26 | AM18: 12 | AN18: 19 | AO18: =SUM(C18:AN18) -> 564 | AP18: =AO18/17 -> 33.176471
A19: 11 | B19: =('1st Term'!B19) -> HAMZAT AKOREDE | C19: 28 | D19: 27 | E19: 17 | F19: 42 | G19: 15 | H19: 34 | I19: 15 | J19: 22 | K19: 17 | L19: 33 | M19: 14 | N19: 15 | O19: 24 | P19: 18 | Q19: 11 | R19: 20 | U19: 14 | V19: 48 | W19: 11 | X19: 32 | Y19: 21 | Z19: 20 | AC19: 16 | AD19: 28 | AE19: 15 | AF19: 30 | AG19: 30 | AH19: 13 | AI19: 11 | AJ19: 7 | AK19: 13 | AL19: 32 | AM19: 12 | AN19: 19 | AO19: =SUM(C19:AN19) -> 724 | AP19: =AO19/17 -> 42.588235
A20: 12 | B20: =('1st Term'!B20) -> JAMES DIVINE | AO20: =SUM(C20:AN20) -> 0 | AP20: =AO20/17 -> 0
A21: 13 | B21: =('1st Term'!B21) -> JOEL JOSHUA | C21: 28 | D21: 36 | E21: 22 | F21: 53 | G21: 27 | H21: 46 | I21: 15 | J21: 22 | K21: 17 | L21: 32 | M21: 14 | N21: 21 | O21: 24 | P21: 34 | Q21: 21 | R21: 45 | U21: 18 | V21: 52 | W21: 19 | X21: 36 | Y21: 20 | Z21: 30 | AC21: 22 | AD21: 22 | AE21: 20 | AF21: 16 | AG21: 29 | AH21: 22 | AI21: 22 | AJ21: 37 | AK21: 17 | AL21: 29 | AM21: 13 | AN21: 30 | AO21: =SUM(C21:AN21) -> 911 | AP21: =AO21/17 -> 53.588235
A22: 14 | B22: =('1st Term'!B22) -> JOSIAH SUNDAY | C22: 28 | D22: 36 | E22: 25 | F22: 38 | G22: 30 | H22: 36 | I22: 15 | J22: 25 | K22: 24 | L22: 24 | M22: 14 | N22: 21 | O22: 20 | P22: 33 | Q22: 20 | R22: 35 | U22: 19 | V22: 50 | W22: 24 | X22: 27 | Y22: 20 | Z22: 30 | AC22: 22 | AD22: 21 | AE22: 30 | AF22: 60 | AG22: 28 | AH22: 18 | AI22: 19 | AJ22: 37 | AK22: 17 | AL22: 33 | AM22: 24 | AN22: 34 | AO22: =SUM(C22:AN22) -> 937 | AP22: =AO22/17 -> 55.117647
A23: 15 | B23: =('1st Term'!B23) -> KUFRE GOODNEWS | C23: 28 | D23: 30 | E23: 20 | F23: 44 | G23: 26 | H23: 65 | I23: 16 | J23: 20 | K23: 13 | L23: 22 | M23: 15 | N23: 14 | O23: 23 | P23: 26 | Q23: 17 | R23: 29 | U23: 17 | V23: 40 | W23: 18 | X23: 37 | Y23: 25 | Z23: 25 | AC23: 12 | AD23: 30 | AE23: 20 | AF23: 10 | AG23: 29 | AH23: 35 | AI23: 22 | AJ23: 23 | AK23: 16 | AL23: 29 | AM23: 22 | AN23: 15 | AO23: =SUM(C23:AN23) -> 833 | AP23: =AO23/17 -> 49
A24: 16 | B24: =('1st Term'!B24) -> NWABUEZE FAVOUR | C24: 28 | D24: 60 | E24: 30 | F24: 63 | G24: 30 | H24: 66 | I24: 22 | J24: 33 | K24: 30 | L24: 54 | M24: 19 | N24: 44 | O24: 25 | P24: 35 | Q24: 22 | R24: 40 | U24: 25 | V24: 52 | W24: 29 | X24: 65 | Y24: 23 | Z24: 47 | AC24: 30 | AD24: 52 | AE24: 20 | AF24: 54 | AG24: 27 | AH24: 40 | AI24: 28 | AJ24: 52 | AK24: 27 | AL24: 60 | AM24: 20 | AN24: 63 | AO24: =SUM(C24:AN24) -> 1315 | AP24: =AO24/17 -> 77.352941
A25: 17 | B25: =('1st Term'!B25) -> NWABUEZE VICTOR | C25: 28 | D25: 26 | E25: 20 | F25: 61 | G25: 17 | H25: 48 | I25: 14 | J25: 12 | K25: 17 | L25: 26 | M25: 13 | N25: 13 | O25: 26 | P25: 27 | Q25: 19 | R25: 35 | U25: 14 | V25: 24 | W25: 22 | X25: 34 | Y25: 20 | Z25: 25 | AC25: 12 | AD25: 21 | AE25: 25 | AF25: 18 | AG25: 28 | AH25: 30 | AI25: 18 | AJ25: 22 | AK25: 21 | AL25: 43 | AM25: 17 | AN25: 30 | AO25: =SUM(C25:AN25) -> 826 | AP25: =AO25/17 -> 48.588235
A26: 18 | B26: =('1st Term'!B26) -> ONYINYECHI ANITA | C26: 28 | D26: 60 | E26: 26 | F26: 55 | G26: 30 | H26: 69 | I26: 20 | J26: 35 | K26: 30 | L26: 59 | M26: 27 | N26: 31 | O26: 23 | P26: 38 | Q26: 29 | R26: 59 | U26: 16 | V26: 58 | W26: 29 | X26: 59 | Y26: 25 | Z26: 40 | AC26: 24 | AD26: 53 | AE26: 25 | AF26: 21 | AG26: 27 | AH26: 50 | AI26: 27 | AJ26: 43 | AK26: 20 | AL26: 65 | AM26: 25 | AN26: 50 | AO26: =SUM(C26:AN26) -> 1276 | AP26: =AO26/17 -> 75.058824
A27: 19 | B27: =('1st Term'!B27) -> ORIAKU BRIGHT | C27: 28 | D27: 26 | E27: 24 | F27: 29 | G27: 30 | H27: 69 | I27: 17 | J27: 20 | K27: 21 | L27: 26 | M27: 16 | N27: 26 | O27: 20 | P27: 28 | Q27: 17 | R27: 22 | U27: 20 | V27: 55 | W27: 18 | X27: 23 | Y27: 23 | Z27: 38 | AC27: 12 | AD27: 26 | AE27: 20 | AF27: 53 | AG27: 27 | AH27: 35 | AI27: 26 | AJ27: 29 | AK27: 18 | AL27: 44 | AM27: 24 | AN27: 42 | AO27: =SUM(C27:AN27) -> 952 | AP27: =AO27/17 -> 56
A28: 20 | B28: =('1st Term'!B28) -> SAKA FAREED | C28: 30 | D28: 68 | E28: 30 | F28: 63 | G28: 30 | H28: 69 | I28: 20 | J28: 30 | K28: 23 | L28: 50 | M28: 23 | N28: 41 | O28: 26 | P28: 28 | Q28: 27 | R28: 65 | U28: 16 | V28: 33 | W28: 28 | X28: 56 | Y28: 24 | Z28: 46 | AC28: 19 | AD28: 33 | AE28: 30 | AF28: 64 | AG28: 30 | AH28: 64 | AI28: 24 | AJ28: 36 | AK28: 19 | AL28: 57 | AM28: 25 | AN28: 51 | AO28: =SUM(C28:AN28) -> 1278 | AP28: =AO28/17 -> 75.176471
A29: 21 | B29: =('1st Term'!B29) -> VICTOR LOVETH | C29: 28 | D29: 62 | E29: 27 | F29: 61 | G29: 30 | H29: 64 | I29: 22 | J29: 43 | K29: 30 | L29: 62 | M29: 21 | N29: 20 | O29: 25 | P29: 45 | Q29: 22 | R29: 48 | U29: 27 | V29: 61 | W29: 29 | X29: 52 | Y29: 22 | Z29: 38 | AC29: 29 | AD29: 16 | AE29: 25 | AF29: 45 | AG29: 27 | AH29: 45 | AI29: 25 | AJ29: 29 | AK29: 25 | AL29: 45 | AM29: 27 | AN29: 47 | AO29: =SUM(C29:AN29) -> 1224 | AP29: =AO29/17 -> 72
A30: 22 | B30: =('1st Term'!B30) -> WASIU NIMOTALLAH | C30: 28 | D30: 28 | E30: 24 | F30: 60 | G30: 26 | H30: 47 | I30: 15 | J30: 20 | K30: 30 | L30: 45 | M30: 13 | N30: 34 | O30: 23 | P30: 36 | Q30: 18 | R30: 35 | U30: 21 | V30: 51 | W30: 16 | X30: 55 | Y30: 22 | Z30: 38 | AC30: 14 | AD30: 31 | AE30: 20 | AF30: 35 | AG30: 26 | AH30: 30 | AI30: 20 | AJ30: 32 | AK30: 13 | AL30: 29 | AM30: 26 | AN30: 66 | AO30: =SUM(C30:AN30) -> 1027 | AP30: =AO30/17 -> 60.411765
A31: 23 | AO31: =SUM(C31:AN31) -> 0 | AP31: =AO31/17 -> 0
A32: 24 | AO32: =SUM(C32:AN32) -> 0 | AP32: =AO32/17 -> 0
A33: 25 | AO33: =SUM(C33:AN33) -> 0 | AP33: =AO33/17 -> 0
A34: 26 | AO34: =SUM(C34:AN34) -> 0 | AP34: =AO34/17 -> 0
A35: 27 | AO35: =SUM(C35:AN35) -> 0 | AP35: =AO35/17 -> 0
A36: 28 | AO36: =SUM(C36:AN36) -> 0 | AP36: =AO36/17 -> 0
A37: 29 | AO37: =SUM(C37:AN37) -> 0 | AP37: =AO37/17 -> 0
A38: 30 | AO38: =SUM(C38:AN38) -> 0 | AP38: =AO38/17 -> 0
A39: 31 | AO39: =SUM(C39:AN39) -> 0 | AP39: =AO39/17 -> 0
A40: 32 | AO40: =SUM(C40:AN40) -> 0 | AP40: =AO40/17 -> 0
A41: 33 | AO41: =SUM(C41:AN41) -> 0 | AP41: =AO41/17 -> 0
A42: 34 | AO42: =SUM(C42:AN42) -> 0 | AP42: =AO42/17 -> 0
...

Sheet 3rd Term
A1: EASYNETT INT'L COLLEGE OF TECH. (EICT)
A3: 76, WILMER CRESCENT, OLODI-APAPA, LAGOS
A4: SESSION | C4: 2025/2026
B5: THIRD TERM | C5: BROADSHEET | AO5: CUMMULATIVE SCORE
A7: S/NO | B7: JSS 1A | C7: AGRICULTURAL SCIENCE | E7: BASIC SCIENCE | G7: BASIC TECH | I7: BUSINESS STUDIES | K7: CULTURAL & CREATIVE ART | L7: 10 | M7: CIVIC EDUCATION | N7: 12 | O7: CHRISTIAN RELIGIOUS STUDIES | Q7: ENGLISH LANGUAGE | S7: ENGLISH PHONETICS | U7: FRENCH | W7: HISTORY | Y7: HOME ECONOMICS | AA7: IGBO LANGUAGE | AC7: INFORMATION TECHNOLOGY | AE7: MATHEMATICS | AG7: PHYSICAL & HEALTH EDUCATION | AI7: SECURITY EDUCATION | AK7: SOCIAL STUDIES | AM7: YORUBA LANGUAGE | AO7: TOTAL | AP7: AVERAGE
B8: STUDENT NAME | C8: CA | D8: EXAM | E8: CA | F8: EXAM | G8: CA | H8: EXAM | I8: CA | J8: EXAM | K8: CA | L8: EXAM | M8: CA | N8: EXAM | O8: CA | P8: EXAM | Q8: CA | R8: EXAM | S8: CA | T8: EXAM | U8: CA | V8: EXAM | W8: CA | X8: EXAM | Y8: CA | Z8: EXAM | AA8: CA | AB8: EXAM | AC8: CA | AD8: EXAM | AE8: CA | AF8: EXAM | AG8: CA | AH8: EXAM | AI8: CA | AJ8: EXAM | AK8: CA | AL8: EXAM | AM8: CA | AN8: EXAM
A9: 1 | B9: =('1st Term'!B9) -> ADAKARAZA SAMUEL | C9: 24 | D9: 50 | E9: 22 | F9: 38 | G9: 27 | H9: 47 | I9: 24 | J9: 43 | K9: 21 | L9: 30 | M9: 25 | N9: 43 | O9: 28 | P9: 41 | Q9: 23 | R9: 32 | U9: 21 | V9: 48 | W9: 15 | X9: 42 | Y9: 24 | Z9: 40 | AC9: 21 | AD9: 20 | AE9: 29 | AF9: 40 | AG9: 24 | AH9: 44 | AI9: 23 | AJ9: 32 | AK9: 26 | AL9: 45 | AM9: 25 | AN9: 57 | AO9: =SUM(C9:AN9) -> 1094 | AP9: =AO9/17 -> 64.352941
A10: 2 | B10: =('1st Term'!B10) -> ADEOLA PEDRO | C10: 21 | D10: 21 | E10: 20 | F10: 35 | G10: 13 | H10: 34 | I10: 25 | J10: 27 | K10: 14 | L10: 30 | M10: 22 | N10: 24 | O10: 23 | P10: 21 | Q10: 20 | R10: 37 | U10: 15 | V10: 27 | W10: 15 | X10: 17 | Y10: 9 | Z10: 27 | AC10: 19 | AD10: 12 | AE10: 29 | AF10: 16 | AG10: 21 | AH10: 18 | AI10: 16 | AJ10: 17 | AK10: 19 | AL10: 31 | AM10: 13 | AN10: 6 | AO10: =SUM(C10:AN10) -> 714 | AP10: =AO10/17 -> 42
A11: 3 | B11: =('1st Term'!B11) -> ASAMS DANIELLA | C11: 20 | D11: 32 | E11: 20 | F11: 21 | G11: 8 | H11: 33 | I11: 24 | J11: 36 | K11: 16 | L11: 34 | M11: 19 | N11: 35 | O11: 25 | P11: 23 | Q11: 15 | R11: 38 | U11: 15 | V11: 42 | W11: 23 | X11: 30 | Y11: 23 | Z11: 28 | AC11: 19 | AD11: 13 | AE11: 30 | AF11: 13 | AG11: 20 | AH11: 41 | AI11: 25 | AJ11: 27 | AK11: 24 | AL11: 46 | AM11: 9 | AN11: 24 | AO11: =SUM(C11:AN11) -> 851 | AP11: =AO11/17 -> 50.058824
A12: 4 | B12: =('1st Term'!B12) -> ASIBOR NANCY | C12: 24 | D12: 49 | E12: 22 | F12: 46 | G12: 22 | H12: 42 | I12: 24 | J12: 41 | K12: 18 | L12: 37 | M12: 26 | N12: 47 | O12: 29 | P12: 39 | Q12: 15 | R12: 61 | U12: 18 | V12: 56 | W12: 26 | X12: 58 | Y12: 28 | Z12: 34 | AC12: 21 | AD12: 17 | AE12: 30 | AF12: 36 | AG12: 24 | AH12: 43 | AI12: 17 | AJ12: 40 | AK12: 26 | AL12: 56 | AM12: 17 | AN12: 33 | AO12: =SUM(C12:AN12) -> 1122 | AP12: =AO12/17 -> 66
A13: 5 | B13: =('1st Term'!B13) -> BANKOLE AMEERAT | C13: 21 | D13: 64 | E13: 24 | F13: 44 | G13: 19 | H13: 54 | I13: 23 | J13: 31 | K13: 16 | L13: 36 | M13: 19 | N13: 30 | O13: 25 | P13: 32 | Q13: 20 | R13: 50 | U13: 17 | V13: 42 | W13: 24 | X13: 44 | Y13: 20 | Z13: 38 | AC13: 15 | AD13: 24 | AE13: 28 | AF13: 26 | AG13: 21 | AH13: 55 | AI13: 26 | AJ13: 40 | AK13: 22 | AL13: 46 | AM13: 14 | AN13: 22 | AO13: =SUM(C13:AN13) -> 1032 | AP13: =AO13/17 -> 60.705882
A14: 6 | B14: =('1st Term'!B14) -> CHIEKEZIE MAXWELL | C14: 20 | D14: 48 | E14: 24 | F14: 45 | G14: 18 | H14: 48 | I14: 26 | J14: 48 | K14: 19 | L14: 36 | M14: 29 | N14: 50 | O14: 28 | P14: 32 | Q14: 13 | R14: 45 | U14: 26 | V14: 46 | W14: 27 | X14: 59 | Y14: 25 | Z14: 45 | AC14: 22 | AD14: 34 | AE14: 28 | AF14: 24 | AG14: 20 | AH14: 58 | AI14: 21 | AJ14: 47 | AK14: 28 | AL14: 52 | AM14: 20 | AN14: 39 | AO14: =SUM(C14:AN14) -> 1150 | AP14: =AO14/17 -> 67.647059
A15: 7 | B15: =('1st Term'!B15) -> EDET MOSES | C15: 22 | D15: 48 | E15: 15 | F15: 37 | G15: 19 | H15: 31 | I15: 20 | J15: 25 | K15: 15 | L15: 30 | M15: 19 | N15: 21 | O15: 25 | P15: 25 | Q15: 18 | R15: 21 | U15: 13 | V15: 23 | W15: 15 | X15: 51 | Y15: 25 | Z15: 25 | AC15: 15 | AD15: 12 | AE15: 30 | AF15: 21 | AG15: 22 | AH15: 30 | AI15: 19 | AJ15: 30 | AK15: 20 | AL15: 46 | AM15: 12 | AN15: 16 | AO15: =SUM(C15:AN15) -> 816 | AP15: =AO15/17 -> 48
A16: 8 | B16: =('1st Term'!B16) -> ENEJOH PHINEHAS | C16: 21 | D16: 64 | E16: 22 | F16: 45 | G16: 20 | H16: 48 | I16: 20 | J16: 32 | K16: 21 | L16: 30 | M16: 26 | N16: 46 | O16: 29 | P16: 22 | Q16: 22 | R16: 61 | U16: 22 | V16: 44 | W16: 17 | X16: 46 | Y16: 27 | Z16: 25 | AC16: 21 | AD16: 20 | AE16: 29 | AF16: 26 | AG16: 21 | AH16: 45 | AI16: 16 | AJ16: 15 | AK16: 28 | AL16: 51 | AM16: 23 | AN16: 32 | AO16: =SUM(C16:AN16) -> 1037 | AP16: =AO16/17 -> 61
A17: 9 | B17: =('1st Term'!B17) -> EWELUKWA FAVOUR | C17: 19 | D17: 24 | E17: 17 | F17: 31 | G17: 2 | H17: 16 | I17: 21 | J17: 15 | K17: 14 | L17: 30 | M17: 15 | N17: 17 | O17: 27 | P17: 21 | Q17: 11 | R17: 18 | U17: 16 | V17: 33 | W17: 15 | X17: 11 | Y17: 19 | Z17: 24 | AC17: 16 | AD17: 11 | AE17: 29 | AF17: 22 | AG17: 19 | AH17: 35 | AI17: 17 | AJ17: 26 | AK17: 16 | AL17: 27 | AM17: 18 | AN17: 19 | AO17: =SUM(C17:AN17) -> 671 | AP17: =AO17/17 -> 39.470588
A18: 10 | B18: =('1st Term'!B18) -> HAMMED OLAMIDE | C18: 21 | D18: 31 | E18: 21 | F18: 47 | G18: 19 | H18: 45 | I18: 20 | J18: 25 | K18: 17 | L18: 32 | M18: 21 | N18: 46 | O18: 28 | P18: 30 | Q18: 13 | R18: 17 | U18: 30 | V18: 60 | W18: 27 | X18: 27 | Y18: 25 | Z18: 28 | AC18: 19 | AD18: 31 | AE18: 30 | AF18: 11 | AG18: 21 | AH18: 40 | AI18: 17 | AJ18: 26 | AK18: 24 | AL18: 43 | AM18: 3 | AN18: 8 | AO18: =SUM(C18:AN18) -> 903 | AP18: =AO18/17 -> 53.117647
A19: 11 | B19: =('1st Term'!B19) -> HAMZAT AKOREDE | C19: 24 | D19: 53 | E19: 25 | F19: 38 | G19: 25 | H19: 30 | I19: 23 | J19: 43 | K19: 20 | L19: 36 | M19: 21 | N19: 37 | O19: 27 | P19: 40 | Q19: 23 | R19: 59 | U19: 17 | V19: 33 | W19: 26 | X19: 61 | Y19: 27 | Z19: 43 | AC19: 20 | AD19: 13 | AE19: 28 | AF19: 23 | AG19: 24 | AH19: 54 | AI19: 21 | AJ19: 45 | AK19: 27 | AL19: 54 | AM19: 20 | AN19: 36 | AO19: =SUM(C19:AN19) -> 1096 | AP19: =AO19/17 -> 64.470588
A20: 12 | B20: =('1st Term'!B20) -> JAMES DIVINE | C20: 12 | D20: 14 | E20: 16 | F20: 27 | G20: 24 | H20: 28 | I20: 20 | J20: 26 | K20: 16 | L20: 30 | M20: 19 | N20: 21 | O20: 17 | P20: 6 | Q20: 19 | R20: 26 | U20: 15 | V20: 46 | W20: 18 | X20: 5 | Y20: 24 | Z20: 36 | AC20: 15 | AD20: 8 | AE20: 30 | AF20: 17 | AG20: 22 | AH20: 36 | AI20: 13 | AJ20: 16 | AK20: 16 | AL20: 26 | AM20: 11 | AN20: 10 | AO20: =SUM(C20:AN20) -> 685 | AP20: =AO20/17 -> 40.294118
... A30: 22 | B30: =('1st Term'!B30) -> WASIU NIMOTALLAH | C30: 27 | D30: 62 | E30: 27 | F30: 60 | G30: 25 | H30: 59 | I30: 21 | J30: 48 | K30: 22 | L30: 38 | M30: 27 | N30: 45 | O30: 28 | P30: 40 | Q30: 28 | R30: 58 | U30: 23 | V30: 47 | W30: 22 | X30: 64 | Y30: 26 | Z30: 50 | AC30: 21 | AD30: 42 | AE30: 28 | AF30: 30 | AG30: 27 | AH30: 65 | AI30: 23 | AJ30: 51 | AK30: 27 | AL30: 50 | AM30: 23 | AN30: 39 | AO30: =SUM(C30:AN30) -> 1273 | AP30: =AO30/17 -> 74.882353
A31: 23 | AO31: =SUM(C31:AN31) -> 0 | AP31: =AO31/17 -> 0
A32: 24 | AO32: =SUM(C32:AN32) -> 0 | AP32: =AO32/17 -> 0
A33: 25 | AO33: =SUM(C33:AN33) -> 0 | AP33: =AO33/17 -> 0
A34: 26 | AO34: =SUM(C34:AN34) -> 0 | AP34: =AO34/17 -> 0
A35: 27 | AO35: =SUM(C35:AN35) -> 0 | AP35: =AO35/17 -> 0
A36: 28 | AO36: =SUM(C36:AN36) -> 0 | AP36: =AO36/17 -> 0
A37: 29 | AO37: =SUM(C37:AN37) -> 0 | AP37: =AO37/17 -> 0
A38: 30 | AO38: =SUM(C38:AN38) -> 0 | AP38: =AO38/17 -> 0
A39: 31 | AO39: =SUM(C39:AN39) -> 0 | AP39: =AO39/17 -> 0
A40: 32 | AO40: =SUM(C40:AN40) -> 0 | AP40: =AO40/17 -> 0
A41: 33 | AO41: =SUM(C41:AN41) -> 0 | AP41: =AO41/17 -> 0
A42: 34 | AO42: =SUM(C42:AN42) -> 0 | AP42: =AO42/17 -> 0
... A48: 40 | AO48: =SUM(C48:AN48) -> 0 | AP48: =AO48/17 -> 0

Sheet comments
A1: EASYNETT INT'L COLLEGE OF TECH. | BA1: ADDITIONAL DETAILS
A3: 76, WILMER CRESCENT, OLODI-APAPA, LAGOS
A4: SESSION | C4: 2025/2026
A5: S/NO | B5: THIRD TERM | C5: NO OF TIMES SCHOOL OPENED | D5: NUMBER IN CLASS | E5: NEXT TERM BEGINS
C6: 110 | D6: 22 | E6: 20TH APRIL 2026
B7: STUDENT NAME | C7: NO OF TIMES PRESENT | D7: CLASS AVERAGE | E7: POSITION | F7: GENDER | G7: Intentionally Left Blank | H7: CLASS TEACHER'S REMARK | O7: PRINCIPAL'S COMMENT | BA7: CLASS TEACHER'S REMARK | BB7: PRINCIPAL'S COMMENT
A8: 1 | B8: =('1st Term'!B9) -> ADAKARAZA SAMUEL | D8: =IFERROR((('1st Term'!AP9)+('2nd Term'!AP9)+('3rd Term'!AP9))/((--('1st Term'!AP9>0))+(--('2nd Term'!AP9>0))+(--('3rd Term'!AP9>0))),"-") -> 46.666667 | E8: =RANK(D8,$D$8:$D$29)&IF(OR(RANK(D8,$D$8:$D$29)=11,RANK(D8,$D$8:$D$29)=12,RANK(D8,$D$8:$D$29)=13),"th",CHOOSE(MIN(5,MOD(RANK(D8,$D$8:$D$29),10)+1),"th","st","nd","rd","th")) -> 20th | F8: Male | H8: He is sometimes playful in class and needs to concentrate more. | O8: Poor result. Learn to devote time to private/personal studies. Promoted to the Next Class. | BA8: He is well behaved and obedient | BB8: A good result, you still need to work harder on your present scores.
A9: 2 | B9: =('1st Term'!B10) -> ADEOLA PEDRO | D9: =IFERROR((('1st Term'!AP10)+('2nd Term'!AP10)+('3rd Term'!AP10))/((--('1st Term'!AP10>0))+(--('2nd Term'!AP10>0))+(--('3rd Term'!AP10>0))),"-") -> 51.019608 | E9: =RANK(D9,$D$8:$D$29)&IF(OR(RANK(D9,$D$8:$D$29)=11,RANK(D9,$D$8:$D$29)=12,RANK(D9,$D$8:$D$29)=13),"th",CHOOSE(MIN(5,MOD(RANK(D9,$D$8:$D$29),10)+1),"th","st","nd","rd","th")) -> 14th | F9: Male | H9: He can perform better with greater commitment and focus. | O9: Excellent performance. Promoted to the Next Class. | BA9: He is always gentle and sociable | BB9: Fairly good. Give greater attention to your study next term
A10: 3 | B10: =('1st Term'!B11) -> ASAMS DANIELLA | D10: =IFERROR((('1st Term'!AP11)+('2nd Term'!AP11)+('3rd Term'!AP11))/((--('1st Term'!AP11>0))+(--('2nd Term'!AP11>0))+(--('3rd Term'!AP11>0))),"-") -> 58.431373 | E10: =RANK(D10,$D$8:$D$29)&IF(OR(RANK(D10,$D$8:$D$29)=11,RANK(D10,$D$8:$D$29)=12,RANK(D10,$D$8:$D$29)=13),"th",CHOOSE(MIN(5,MOD(RANK(D10,$D$8:$D$29),10)+1),"th","st","nd","rd","th")) -> 8th | F10: Female | H10: He is sometimes playful in class and needs to concentrate more. | O10: Just fair. You can improve if only you will be more regular at school next term. Promoted to the Next Class. | BA10: She is always neat and punctual to school | BB10: This is good result. Keep working hard
A11: 4 | B11: =('1st Term'!B12) -> ASIBOR NANCY | D11: =IFERROR((('1st Term'!AP12)+('2nd Term'!AP12)+('3rd Term'!AP12))/((--('1st Term'!AP12>0))+(--('2nd Term'!AP12>0))+(--('3rd Term'!AP12>0))),"-") -> 66.352941 | E11: =RANK(D11,$D$8:$D$29)&IF(OR(RANK(D11,$D$8:$D$29)=11,RANK(D11,$D$8:$D$29)=12,RANK(D11,$D$8:$D$29)=13),"th",CHOOSE(MIN(5,MOD(RANK(D11,$D$8:$D$29),10)+1),"th","st","nd","rd","th")) -> 3rd | F11: Female | H11: She is improving gradually but needs to participate more in class discussions. | O11: Just fair. You can improve if only you will be more regular at school next term. Promoted to the Next Class. | BA11: She is gentle and neat | BB11: This performance is satisfactory.
A12: 5 | B12: =('1st Term'!B13) -> BANKOLE AMEERAT | D12: =IFERROR((('1st Term'!AP13)+('2nd Term'!AP13)+('3rd Term'!AP13))/((--('1st Term'!AP13>0))+(--('2nd Term'!AP13>0))+(--('3rd Term'!AP13>0))),"-") -> 71.352941 | E12: =RANK(D12,$D$8:$D$29)&IF(OR(RANK(D12,$D$8:$D$29)=11,RANK(D12,$D$8:$D$29)=12,RANK(D12,$D$8:$D$29)=13),"th",CHOOSE(MIN(5,MOD(RANK(D12,$D$8:$D$29),10)+1),"th","st","nd","rd","th")) -> 1st | F12: Female | H12: She is improving gradually but needs to participate more in class discussions. | O12: Just fair. You can improve if only you will be more regular at school next term. Promoted to the Next Class. | BA12: He is an obedient student | BB12: Good performance. Keep it up
A13: 6 | B13: =('1st Term'!B14) -> CHIEKEZIE MAXWELL | D13: =IFERROR((('1st Term'!AP14)+('2nd Term'!AP14)+('3rd Term'!AP14))/((--('1st Term'!AP14>0))+(--('2nd Term'!AP14>0))+(--('3rd Term'!AP14>0))),"-") -> 47.215686 | E13: =RANK(D13,$D$8:$D$29)&IF(OR(RANK(D13,$D$8:$D$29)=11,RANK(D13,$D$8:$D$29)=12,RANK(D13,$D$8:$D$29)=13),"th",CHOOSE(MIN(5,MOD(RANK(D13,$D$8:$D$29),10)+1),"th","st","nd","rd","th")) -> 18th | F13: Male | H13: She is improving gradually but needs to participate more in class discussions. | O13: Just fair. You can improve if only you will be more regular at school next term. Promoted to the Next Class. | BA13: He is respectful and always neat | BB13: Fair result. You can improve in your weak subjects
A14: 7 | B14: =('1st Term'!B15) -> EDET MOSES | D14: =IFERROR((('1st Term'!AP15)+('2nd Term'!AP15)+('3rd Term'!AP15))/((--('1st Term'!AP15>0))+(--('2nd Term'!AP15>0))+(--('3rd Term'!AP15>0))),"-") -> 51.137255 | E14: =RANK(D14,$D$8:$D$29)&IF(OR(RANK(D14,$D$8:$D$29)=11,RANK(D14,$D$8:$D$29)=12,RANK(D14,$D$8:$D$29)=13),"th",CHOOSE(MIN(5,MOD(RANK(D14,$D$8:$D$29),10)+1),"th","st","nd","rd","th")) -> 12th | F14: Male | H14: She is improving gradually but needs to participate more in class discussions. | O14: Just fair. You can improve if only you will be more regular at school next term. Promoted to the Next Class. | BA14: He is always neat and obedient | BB14: Fairly good result. You need to work extra hard in your weak subjects area
A15: 8 | B15: =('1st Term'!B16) -> ENEJOH PHINEHAS | D15: =IFERROR((('1st Term'!AP16)+('2nd Term'!AP16)+('3rd Term'!AP16))/((--('1st Term'!AP16>0))+(--('2nd Term'!AP16>0))+(--('3rd Term'!AP16>0))),"-") -> 49.196078 | E15: =RANK(D15,$D$8:$D$29)&IF(OR(RANK(D15,$D$8:$D$29)=11,RANK(D15,$D$8:$D$29)=12,RANK(D15,$D$8:$D$29)=13),"th",CHOOSE(MIN(5,MOD(RANK(D15,$D$8:$D$29),10)+1),"th","st","nd","rd","th")) -> 15th | F15: Male | H15: She is improving gradually but needs to participate more in class discussions. | O15: Just fair. You can improve if only you will be more regular at school next term. Promoted to the Next Class. | BA15: He is respectful and obedient | BB15: Good result. Try to put more effort in your weak areas
A16: 9 | B16: =('1st Term'!B17) -> EWELUKWA FAVOUR | D16: =IFERROR((('1st Term'!AP17)+('2nd Term'!AP17)+('3rd Term'!AP17))/((--('1st Term'!AP17>0))+(--('2nd Term'!AP17>0))+(--('3rd Term'!AP17>0))),"-") -> 58.117647 | E16: =RANK(D16,$D$8:$D$29)&IF(OR(RANK(D16,$D$8:$D$29)=11,RANK(D16,$D$8:$D$29)=12,RANK(D16,$D$8:$D$29)=13),"th",CHOOSE(MIN(5,MOD(RANK(D16,$D$8:$D$29),10)+1),"th","st","nd","rd","th")) -> 10th | F16: Female | H16: She is improving gradually but needs to participate more in class discussions. | O16: Just fair. You can improve if only you will be more regular at school next term. Promoted to the Next Class. | BA16: She is brilliant and industrious | BB16: Very good. You have performed so well. Keep up the good work
A17: 10 | B17: =('1st Term'!B18) -> HAMMED OLAMIDE | D17: =IFERROR((('1st Term'!AP18)+('2nd Term'!AP18)+('3rd Term'!AP18))/((--('1st Term'!AP18>0))+(--('2nd Term'!AP18>0))+(--('3rd Term'!AP18>0))),"-") -> 36.843137 | E17: =RANK(D17,$D$8:$D$29)&IF(OR(RANK(D17,$D$8:$D$29)=11,RANK(D17,$D$8:$D$29)=12,RANK(D17,$D$8:$D$29)=13),"th",CHOOSE(MIN(5,MOD(RANK(D17,$D$8:$D$29),10)+1),"th","st","nd","rd","th")) -> 22nd | F17: Male | H17: She is improving gradually but needs to participate more in class discussions. | O17: Just fair. You can improve if only you will be more regular at school next term. Promoted to the Next Class. | BA17: He is intelligent, obedient and hardworking | BB17: Good performances. Work harder on your weak areas
A18: 11 | B18: =('1st Term'!B19) -> HAMZAT AKOREDE | D18: =IFERROR((('1st Term'!AP19)+('2nd Term'!AP19)+('3rd Term'!AP19))/((--('1st Term'!AP19>0))+(--('2nd Term'!AP19>0))+(--('3rd Term'!AP19>0))),"-") -> 46.862745 | E18: =RANK(D18,$D$8:$D$29)&IF(OR(RANK(D18,$D$8:$D$29)=11,RANK(D18,$D$8:$D$29)=12,RANK(D18,$D$8:$D$29)=13),"th",CHOOSE(MIN(5,MOD(RANK(D18,$D$8:$D$29),10)+1),"th","st","nd","rd","th")) -> 19th | F18: Male | H18: She is improving gradually but needs to participate more in class discussions. | O18: Just fair. You can improve if only you will be more regular at school next term. Promoted to the Next Class. | BA18: He is brilliant, hardworking and industrious | BB18: Good result but you can do better than this
A19: 12 | B19: =('1st Term'!B20) -> JAMES DIVINE | D19: =IFERROR((('1st Term'!AP20)+('2nd Term'!AP20)+('3rd Term'!AP20))/((--('1st Term'!AP20>0))+(--('2nd Term'!AP20>0))+(--('3rd Term'!AP20>0))),"-") -> 39.088235 | E19: =RANK(D19,$D$8:$D$29)&IF(OR(RANK(D19,$D$8:$D$29)=11,RANK(D19,$D$8:$D$29)=12,RANK(D19,$D$8:$D$29)=13),"th",CHOOSE(MIN(5,MOD(RANK(D19,$D$8:$D$29),10)+1),"th","st","nd","rd","th")) -> 21st | F19: Male | H19: She is improving gradually but needs to participate more in class discussions. | O19: Just fair. You can improve if only you will be more regular at school next term. Promoted to the Next Class. | BA19: He is well behaved and intelligent | BB19: Very good result. Keep it up
... A29: 22 | B29: =('1st Term'!B30) -> WASIU NIMOTALLAH | D29: =IFERROR((('1st Term'!AP30)+('2nd Term'!AP30)+('3rd Term'!AP30))/((--('1st Term'!AP30>0))+(--('2nd Term'!AP30>0))+(--('3rd Term'!AP30>0))),"-") -> 61.568627 | E29: =RANK(D29,$D$8:$D$29)&IF(OR(RANK(D29,$D$8:$D$29)=11,RANK(D29,$D$8:$D$29)=12,RANK(D29,$D$8:$D$29)=13),"th",CHOOSE(MIN(5,MOD(RANK(D29,$D$8:$D$29),10)+1),"th","st","nd","rd","th")) -> 6th | F29: Female | H29: She is improving gradually but needs to participate more in class discussions. | O29: Just fair. You can improve if only you will be more regular at school next term. Promoted to the Next Class. | BA29: He needs to pay more attention in class to improve his understanding. | BB29: Poor result. Learn to devote time to private/personal studies
A30: 23 | H30: She is improving gradually but needs to participate more in class discussions. | O30: Just fair. You can improve if only you will be more regular at school next term. Promoted to the Next Class. | BA30: She is improving gradually but needs to participate more in class discussions. | BB30: Just fair. You can improve if only you will be more regular at school next term
A31: 24 | H31: She is improving gradually but needs to participate more in class discussions. | O31: Just fair. You can improve if only you will be more regular at school next term. Promoted to the Next Class. | BA31: He should learn to submit assignments on time. | BB31: A good result you still need to work harder on your present scores. Promoted to the Next Class.
A32: 25 | H32: She is improving gradually but needs to participate more in class discussions. | O32: Just fair. You can improve if only you will be more regular at school next term. Promoted to the Next Class. | BA32: She can do better if she avoids distractions during lessons. | BB32: Fairly good. Give greater attention to your study next term. Promoted to the Next Class.
A33: 26 | H33: She is improving gradually but needs to participate more in class discussions. | O33: Just fair. You can improve if only you will be more regular at school next term. Promoted to the Next Class. | BA33: He is sometimes playful in class and needs to concentrate more. | BB33: This is good result. Keep working hard. Promoted to the Next Class.
A34: 27 | H34: She is improving gradually but needs to participate more in class discussions. | O34: Just fair. You can improve if only you will be more regular at school next term. Promoted to the Next Class. | BA34: She tries her best but needs to put in more effort in her weak subjects. | BB34: This performance is satisfactory. Promoted to the Next Class.
A35: 28 | H35: She is improving gradually but needs to participate more in class discussions. | O35: Just fair. You can improve if only you will be more regular at school next term. Promoted to the Next Class. | BA35: He is calm but should be more active in group work. | BB35: Good performance. Keep it up. Promoted to the Next Class.
A36: 29 | H36: She is improving gradually but needs to participate more in class discussions. | O36: Just fair. You can improve if only you will be more regular at school next term. Promoted to the Next Class. | BA36: He is sometimes playful in class and needs to concentrate more. | BB36: Poor. Improve more on your studies to measure up. Learning is not difficult. Promoted to the Next Class.
A37: 30 | H37: She is improving gradually but needs to participate more in class discussions. | O37: Just fair. You can improve if only you will be more regular at school next term. Promoted to the Next Class. | BA37: She tries her best but needs to put in more effort in her weak subjects. | BB37: Excellent performance. Promoted to the Next Class.
A38: 31 | H38: She is improving gradually but needs to participate more in class discussions. | O38: Just fair. You can improve if only you will be more regular at school next term. Promoted to the Next Class. | BA38: He is calm but should be more active in group work. | BB38: Good result. You can improve on this next term. Promoted to the Next Class.
A39: 32 | H39: She is improving gradually but needs to participate more in class discussions. | O39: Just fair. You can improve if only you will be more regular at school next term. Promoted to the Next Class. | BA39: She is responsible but needs to work on her handwriting. | BB39: Very good result. You can still do better. Promoted to the Next Class.
A40: 33 | H40: She is improving gradually but needs to participate more in class discussions. | O40: Just fair. You can improve if only you will be more regular at school next term. Promoted to the Next Class. | BA40: He is improving in behavior but still needs to avoid lateness. | BB40: Poor result. Learn to devote time to private/personal studies. Promoted to the Next Class.
A41: 34 | H41: She is improving gradually but needs to participate more in class discussions. | O41: Just fair. You can improve if only you will be more regular at school next term. Promoted to the Next Class. | BA41: She is obedient but should learn to speak more confidently in class. | BB41: Just fair. You can improve if only you will be more regular at school next term. Promoted to the Next Class.
A42: 35 | H42: She is improving gradually but needs to participate more in class discussions. | O42: Just fair. You can improve if only you will be more regular at school next term. Promoted to the Next Class. | BA42: He shows interest in learning but needs to be more consistent.
A43: 36 | H43: She is improving gradually but needs to participate more in class discussions. | O43: Just fair. You can improve if only you will be more regular at school next term. Promoted to the Next Class. | BA43: She is friendly but talks too much during lessons.
A44: 37 | H44: She is improving gradually but needs to participate more in class discussions. | O44: Just fair. You can improve if only you will be more regular at school next term. Promoted to the Next Class. | BA44: He needs to be more serious with his studies to achieve better results.
A45: 38 | H45: She is improving gradually but needs to participate more in class discussions. | O45: Just fair. You can improve if only you will be more regular at school next term. Promoted to the Next Class. | BA45: She is respectful but sometimes forgets to complete her homework.
A46: 39 | H46: She is improving gradually but needs to participate more in class discussions. | O46: Just fair. You can improve if only you will be more regular at school next term. Promoted to the Next Class. | BA46: He can perform better with greater commitment and focus.
A47: 40 | H47: She is improving gradually but needs to participate more in class discussions. | O47: Just fair. You can improve if only you will be more regular at school next term. Promoted to the Next Class. | BA47: He loses concentration easily and must learn to stay focused during lessons.
BA48: She is irregular in attendance and should be more punctual to school.
BA49: He is careless with his books and needs to be more organized.
BA50: She finds it difficult to follow instructions and must pay closer attention.
...

Sheet sheet1
B1: EASYNETT INT'L COLLEGE OF TECH.
B3: 76, WILMER CRESCENT, OLODI-APAPA, LAGOS
B4: TEL: 07030903097, 08054260717
B5: REPORT CARD
K7: PASSPORT PHOTO
A8: Student Name: | C8: =('1st Term'!B9) -> ADAKARAZA SAMUEL
A9: Class: | C9: =('1st Term'!B7) -> JSS 1A
A10: Session: | C10: =(comments!C4) -> 2025/2026
A11: Term: | C11: =(comments!B5) -> THIRD TERM | F11: Cum Average: | H11: =INDEX(comments!D8:D47,MATCH(sheet1!C8,comments!B8:B47,0)) -> 46.666667
A12: Next Term Begins: | C12: =(comments!E6) -> 20TH APRIL 2026 | F12: Position: | H12: =INDEX(comments!E8:E47,MATCH(sheet1!C8,comments!B8:B47,0)) -> 20th
A14: FREQUENCIES | D14: SCHOOL ATTENDANCE | I14: PSYCHOMOTOR | J14: PUNCTUALITY | M14: D
A15: No. of times School Opened: | D15: =(comments!C6) -> 110 | J15: NEATNESS | M15: C
A16: No. of times Present: | D16: =VLOOKUP(C8,comments!B8:C47,2,FALSE) -> 0 | J16: HONESTY | M16: C
A17: No. in Class: | D17: =(comments!D6) -> 22 | J17: CREATIVITY | M17: D
A18: SUBJECT | F18: Third Term CA | G18: Third Term Exam | H18: Third Term Total | I18: Second Term Score | J18: First Term Score | K18: Cum Total | L18: Cum Average | M18: GRADE
A19: AGRICULTURAL SCIENCE | F19: =VLOOKUP(C8,'3rd Term'!B9:AN48,2,FALSE) -> 24 | G19: =VLOOKUP(C8,'3rd Term'!B9:AN48,3,FALSE) -> 50 | H19: =SUM(F19:G19) -> 74 | I19: =(VLOOKUP(C8,'2nd Term'!B9:AN48,2,FALSE))+(VLOOKUP(C8,'2nd Term'!B9:AN48,3,FALSE)) -> 56 | J19: =(VLOOKUP($C$8,'1st Term'!$B$9:$AN$48,2,FALSE))+(VLOOKUP($C$8,'1st Term'!$B$9:$AN$48,3,FALSE)) -> 56 | K19: =IF(SUM(H19:J19)=0,"-",SUM(H19:J19)) -> 186 | L19: =IFERROR(((H19)+(I19)+(J19))/((--(H19>0))+(--(I19>0))+(--(J19>0))),"-") -> 62 | M19: =IF(L19="-","-",IF(L19>=70,"A",IF(L19>=50,"C",IF(L19>=40,"P","F")))) -> C
A20: BASIC SCIENCE | F20: =VLOOKUP(C8,'3rd Term'!B9:AN48,4,FALSE) -> 22 | G20: =VLOOKUP(C8,'3rd Term'!B9:AN48,5,FALSE) -> 38 | H20: =SUM(F20:G20) -> 60 | I20: =(VLOOKUP(C8,'2nd Term'!B9:AN48,4,FALSE))+(VLOOKUP(C8,'2nd Term'!B9:AN48,5,FALSE)) -> 48 | J20: =(VLOOKUP($C$8,'1st Term'!$B$9:$AN$48,4,FALSE))+(VLOOKUP($C$8,'1st Term'!$B$9:$AN$48,5,FALSE)) -> 56 | K20: =IF(SUM(H20:J20)=0,"-",SUM(H20:J20)) -> 164 | L20: =IFERROR(((H20)+(I20)+(J20))/((--(H20>0))+(--(I20>0))+(--(J20>0))),"-") -> 54.666667 | M20: =IF(L20="-","-",IF(L20>=70,"A",IF(L20>=50,"C",IF(L20>=40,"P","F")))) -> C
A21: BASIC TECH | F21: =VLOOKUP(C8,'3rd Term'!B9:AN48,6,FALSE) -> 27 | G21: =VLOOKUP(C8,'3rd Term'!B9:AN48,7,FALSE) -> 47 | H21: =SUM(F21:G21) -> 74 | I21: =(VLOOKUP(C8,'2nd Term'!B9:AN48,6,FALSE))+(VLOOKUP(C8,'2nd Term'!B9:AN48,7,FALSE)) -> 40 | J21: =(VLOOKUP($C$8,'1st Term'!$B$9:$AN$48,6,FALSE))+(VLOOKUP($C$8,'1st Term'!$B$9:$AN$48,7,FALSE)) -> 25 | K21: =IF(SUM(H21:J21)=0,"-",SUM(H21:J21)) -> 139 | L21: =IFERROR(((H21)+(I21)+(J21))/((--(H21>0))+(--(I21>0))+(--(J21>0))),"-") -> 46.333333 | M21: =IF(L21="-","-",IF(L21>=70,"A",IF(L21>=50,"C",IF(L21>=40,"P","F")))) -> P
A22: BUSINESS STUDIES | F22: =VLOOKUP(C8,'3rd Term'!B9:AN48,8,FALSE) -> 24 | G22: =VLOOKUP(C8,'3rd Term'!B9:AN48,9,FALSE) -> 43 | H22: =SUM(F22:G22) -> 67 | I22: =(VLOOKUP(C8,'2nd Term'!B9:AN48,8,FALSE))+(VLOOKUP(C8,'2nd Term'!B9:AN48,9,FALSE)) -> 40 | J22: =(VLOOKUP($C$8,'1st Term'!$B$9:$AN$48,8,FALSE))+(VLOOKUP($C$8,'1st Term'!$B$9:$AN$48,9,FALSE)) -> 32 | K22: =IF(SUM(H22:J22)=0,"-",SUM(H22:J22)) -> 139 | L22: =IFERROR(((H22)+(I22)+(J22))/((--(H22>0))+(--(I22>0))+(--(J22>0))),"-") -> 46.333333 | M22: =IF(L22="-","-",IF(L22>=70,"A",IF(L22>=50,"C",IF(L22>=40,"P","F")))) -> P
A23: CULTURAL & CREATIVE ART | F23: =VLOOKUP(C8,'3rd Term'!B9:AN48,10,FALSE) -> 21 | G23: =VLOOKUP(C8,'3rd Term'!B9:AN48,11,FALSE) -> 30 | H23: =SUM(F23:G23) -> 51 | I23: =(VLOOKUP(C8,'2nd Term'!B9:AN48,10,FALSE))+(VLOOKUP(C8,'2nd Term'!B9:AN48,11,FALSE)) -> 33 | J23: =(VLOOKUP($C$8,'1st Term'!$B$9:$AN$48,10,FALSE))+(VLOOKUP($C$8,'1st Term'!$B$9:$AN$48,11,FALSE)) -> 33 | K23: =IF(SUM(H23:J23)=0,"-",SUM(H23:J23)) -> 117 | L23: =IFERROR(((H23)+(I23)+(J23))/((--(H23>0))+(--(I23>0))+(--(J23>0))),"-") -> 39 | M23: =IF(L23="-","-",IF(L23>=70,"A",IF(L23>=50,"C",IF(L23>=40,"P","F")))) -> F
A24: CIVIC EDUCATION | F24: =VLOOKUP(C8,'3rd Term'!B9:AN48,12,FALSE) -> 25 | G24: =VLOOKUP(C8,'3rd Term'!B9:AN48,13,FALSE) -> 43 | H24: =SUM(F24:G24) -> 68 | I24: =(VLOOKUP(C8,'2nd Term'!B9:AN48,12,FALSE))+(VLOOKUP(C8,'2nd Term'!B9:AN48,13,FALSE)) -> 30 | J24: =(VLOOKUP($C$8,'1st Term'!$B$9:$AN$48,12,FALSE))+(VLOOKUP($C$8,'1st Term'!$B$9:$AN$48,13,FALSE)) -> 27 | K24: =IF(SUM(H24:J24)=0,"-",SUM(H24:J24)) -> 125 | L24: =IFERROR(((H24)+(I24)+(J24))/((--(H24>0))+(--(I24>0))+(--(J24>0))),"-") -> 41.666667 | M24: =IF(L24="-","-",IF(L24>=70,"A",IF(L24>=50,"C",IF(L24>=40,"P","F")))) -> P
A25: CHRISTIAN RELIGIOUS STUDIES | F25: =VLOOKUP(C8,'3rd Term'!B9:AN48,14,FALSE) -> 28 | G25: =VLOOKUP(C8,'3rd Term'!B9:AN48,15,FALSE) -> 41 | H25: =SUM(F25:G25) -> 69 | I25: =(VLOOKUP(C8,'2nd Term'!B9:AN48,14,FALSE))+(VLOOKUP(C8,'2nd Term'!B9:AN48,15,FALSE)) -> 48 | J25: =(VLOOKUP($C$8,'1st Term'!$B$9:$AN$48,14,FALSE))+(VLOOKUP($C$8,'1st Term'!$B$9:$AN$48,15,FALSE)) -> 51 | K25: =IF(SUM(H25:J25)=0,"-",SUM(H25:J25)) -> 168 | L25: =IFERROR(((H25)+(I25)+(J25))/((--(H25>0))+(--(I25>0))+(--(J25>0))),"-") -> 56 | M25: =IF(L25="-","-",IF(L25>=70,"A",IF(L25>=50,"C",IF(L25>=40,"P","F")))) -> C
A26: ENGLISH LANGUAGE | F26: =VLOOKUP(C8,'3rd Term'!B9:AN48,16,FALSE) -> 23 | G26: =VLOOKUP(C8,'3rd Term'!B9:AN48,17,FALSE) -> 32 | H26: =SUM(F26:G26) -> 55 | I26: =(VLOOKUP(C8,'2nd Term'!B9:AN48,16,FALSE))+(VLOOKUP(C8,'2nd Term'!B9:AN48,17,FALSE)) -> 40 | J26: =(VLOOKUP($C$8,'1st Term'!$B$9:$AN$48,16,FALSE))+(VLOOKUP($C$8,'1st Term'!$B$9:$AN$48,17,FALSE)) -> 24 | K26: =IF(SUM(H26:J26)=0,"-",SUM(H26:J26)) -> 119 | L26: =IFERROR(((H26)+(I26)+(J26))/((--(H26>0))+(--(I26>0))+(--(J26>0))),"-") -> 39.666667 | M26: =IF(L26="-","-",IF(L26>=70,"A",IF(L26>=50,"C",IF(L26>=40,"P","F")))) -> F
A27: ENGLISH PHONETICS | F27: =VLOOKUP(C8,'3rd Term'!B9:AN48,18,FALSE) -> 0 | G27: =VLOOKUP(C8,'3rd Term'!B9:AN48,19,FALSE) -> 0 | H27: =SUM(F27:G27) -> 0 | I27: =(VLOOKUP(C8,'2nd Term'!B9:AN48,18,FALSE))+(VLOOKUP(C8,'2nd Term'!B9:AN48,19,FALSE)) -> 0 | J27: =(VLOOKUP($C$8,'1st Term'!$B$9:$AN$48,18,FALSE))+(VLOOKUP($C$8,'1st Term'!$B$9:$AN$48,19,FALSE)) -> 0 | K27: =IF(SUM(H27:J27)=0,"-",SUM(H27:J27)) -> - | L27: =IFERROR(((H27)+(I27)+(J27))/((--(H27>0))+(--(I27>0))+(--(J27>0))),"-") -> - | M27: =IF(L27="-","-",IF(L27>=70,"A",IF(L27>=50,"C",IF(L27>=40,"P","F")))) -> -
A28: FRENCH | F28: =VLOOKUP(C8,'3rd Term'!B9:AN48,20,FALSE) -> 21 | G28: =VLOOKUP(C8,'3rd Term'!B9:AN48,21,FALSE) -> 48 | H28: =SUM(F28:G28) -> 69 | I28: =(VLOOKUP(C8,'2nd Term'!B9:AN48,20,FALSE))+(VLOOKUP(C8,'2nd Term'!B9:AN48,21,FALSE)) -> 58 | J28: =(VLOOKUP($C$8,'1st Term'!$B$9:$AN$48,20,FALSE))+(VLOOKUP($C$8,'1st Term'!$B$9:$AN$48,21,FALSE)) -> 23 | K28: =IF(SUM(H28:J28)=0,"-",SUM(H28:J28)) -> 150 | L28: =IFERROR(((H28)+(I28)+(J28))/((--(H28>0))+(--(I28>0))+(--(J28>0))),"-") -> 50 | M28: =IF(L28="-","-",IF(L28>=70,"A",IF(L28>=50,"C",IF(L28>=40,"P","F")))) -> C
A29: HISTORY | F29: =VLOOKUP(C8,'3rd Term'!B9:AN48,22,FALSE) -> 15 | G29: =VLOOKUP(C8,'3rd Term'!B9:AN48,23,FALSE) -> 42 | H29: =SUM(F29:G29) -> 57 | I29: =(VLOOKUP(C8,'2nd Term'!B9:AN48,22,FALSE))+(VLOOKUP(C8,'2nd Term'!B9:AN48,23,FALSE)) -> 37 | J29: =(VLOOKUP($C$8,'1st Term'!$B$9:$AN$48,22,FALSE))+(VLOOKUP($C$8,'1st Term'!$B$9:$AN$48,23,FALSE)) -> 26 | K29: =IF(SUM(H29:J29)=0,"-",SUM(H29:J29)) -> 120 | L29: =IFERROR(((H29)+(I29)+(J29))/((--(H29>0))+(--(I29>0))+(--(J29>0))),"-") -> 40 | M29: =IF(L29="-","-",IF(L29>=70,"A",IF(L29>=50,"C",IF(L29>=40,"P","F")))) -> P
A30: HOME ECONOMICS | F30: =VLOOKUP(C8,'3rd Term'!B9:AN48,24,FALSE) -> 24 | G30: =VLOOKUP(C8,'3rd Term'!B9:AN48,25,FALSE) -> 40 | H30: =SUM(F30:G30) -> 64 | I30: =(VLOOKUP(C8,'2nd Term'!B9:AN48,24,FALSE))+(VLOOKUP(C8,'2nd Term'!B9:AN48,25,FALSE)) -> 37 | J30: =(VLOOKUP($C$8,'1st Term'!$B$9:$AN$48,24,FALSE))+(VLOOKUP($C$8,'1st Term'!$B$9:$AN$48,25,FALSE)) -> 44 | K30: =IF(SUM(H30:J30)=0,"-",SUM(H30:J30)) -> 145 | L30: =IFERROR(((H30)+(I30)+(J30))/((--(H30>0))+(--(I30>0))+(--(J30>0))),"-") -> 48.333333 | M30: =IF(L30="-","-",IF(L30>=70,"A",IF(L30>=50,"C",IF(L30>=40,"P","F")))) -> P
A31: IGBO LANGUAGE | F31: =VLOOKUP(C8,'3rd Term'!B9:AN48,26,FALSE) -> 0 | G31: =VLOOKUP(C8,'3rd Term'!B9:AN48,27,FALSE) -> 0 | H31: =SUM(F31:G31) -> 0 | I31: =(VLOOKUP(C8,'2nd Term'!B9:AN48,26,FALSE))+(VLOOKUP(C8,'2nd Term'!B9:AN48,27,FALSE)) -> 0 | J31: =(VLOOKUP($C$8,'1st Term'!$B$9:$AN$48,26,FALSE))+(VLOOKUP($C$8,'1st Term'!$B$9:$AN$48,27,FALSE)) -> 0 | K31: =IF(SUM(H31:J31)=0,"-",SUM(H31:J31)) -> - | L31: =IFERROR(((H31)+(I31)+(J31))/((--(H31>0))+(--(I31>0))+(--(J31>0))),"-") -> - | M31: =IF(L31="-","-",IF(L31>=70,"A",IF(L31>=50,"C",IF(L31>=40,"P","F")))) -> -
A32: INFORMATION TECHNOLOGY | F32: =VLOOKUP(C8,'3rd Term'!B9:AN48,28,FALSE) -> 21 | G32: =VLOOKUP(C8,'3rd Term'!B9:AN48,29,FALSE) -> 20 | H32: =SUM(F32:G32) -> 41 | I32: =(VLOOKUP(C8,'2nd Term'!B9:AN48,28,FALSE))+(VLOOKUP(C8,'2nd Term'!B9:AN48,29,FALSE)) -> 25 | J32: =(VLOOKUP($C$8,'1st Term'!$B$9:$AN$48,28,FALSE))+(VLOOKUP($C$8,'1st Term'!$B$9:$AN$48,29,FALSE)) -> 28 | K32: =IF(SUM(H32:J32)=0,"-",SUM(H32:J32)) -> 94 | L32: =IFERROR(((H32)+(I32)+(J32))/((--(H32>0))+(--(I32>0))+(--(J32>0))),"-") -> 31.333333 | M32: =IF(L32="-","-",IF(L32>=70,"A",IF(L32>=50,"C",IF(L32>=40,"P","F")))) -> F
A33: MATHEMATICS | F33: =VLOOKUP(C8,'3rd Term'!B9:AN48,30,FALSE) -> 29 | G33: =VLOOKUP(C8,'3rd Term'!B9:AN48,31,FALSE) -> 40 | H33: =SUM(F33:G33) -> 69 | I33: =(VLOOKUP(C8,'2nd Term'!B9:AN48,30,FALSE))+(VLOOKUP(C8,'2nd Term'!B9:AN48,31,FALSE)) -> 50 | J33: =(VLOOKUP($C$8,'1st Term'!$B$9:$AN$48,30,FALSE))+(VLOOKUP($C$8,'1st Term'!$B$9:$AN$48,31,FALSE)) -> 40 | K33: =IF(SUM(H33:J33)=0,"-",SUM(H33:J33)) -> 159 | L33: =IFERROR(((H33)+(I33)+(J33))/((--(H33>0))+(--(I33>0))+(--(J33>0))),"-") -> 53 | M33: =IF(L33="-","-",IF(L33>=70,"A",IF(L33>=50,"C",IF(L33>=40,"P","F")))) -> C
A34: PHYSICAL & HEALTH EDUCATION | F34: =VLOOKUP(C8,'3rd Term'!B9:AN48,32,FALSE) -> 24 | G34: =VLOOKUP(C8,'3rd Term'!B9:AN48,33,FALSE) -> 44 | H34: =SUM(F34:G34) -> 68 | I34: =(VLOOKUP(C8,'2nd Term'!B9:AN48,32,FALSE))+(VLOOKUP(C8,'2nd Term'!B9:AN48,33,FALSE)) -> 39 | J34: =(VLOOKUP($C$8,'1st Term'!$B$9:$AN$48,32,FALSE))+(VLOOKUP($C$8,'1st Term'!$B$9:$AN$48,33,FALSE)) -> 39 | K34: =IF(SUM(H34:J34)=0,"-",SUM(H34:J34)) -> 146 | L34: =IFERROR(((H34)+(I34)+(J34))/((--(H34>0))+(--(I34>0))+(--(J34>0))),"-") -> 48.666667 | M34: =IF(L34="-","-",IF(L34>=70,"A",IF(L34>=50,"C",IF(L34>=40,"P","F")))) -> P
A35: SECURITY EDUCATION | F35: =VLOOKUP(C8,'3rd Term'!B9:AN48,34,FALSE) -> 23 | G35: =VLOOKUP(C8,'3rd Term'!B9:AN48,35,FALSE) -> 32 | H35: =SUM(F35:G35) -> 55 | I35: =(VLOOKUP(C8,'2nd Term'!B9:AN48,34,FALSE))+(VLOOKUP(C8,'2nd Term'!B9:AN48,35,FALSE)) -> 31 | J35: =(VLOOKUP($C$8,'1st Term'!$B$9:$AN$48,34,FALSE))+(VLOOKUP($C$8,'1st Term'!$B$9:$AN$48,35,FALSE)) -> 18 | K35: =IF(SUM(H35:J35)=0,"-",SUM(H35:J35)) -> 104 | L35: =IFERROR(((H35)+(I35)+(J35))/((--(H35>0))+(--(I35>0))+(--(J35>0))),"-") -> 34.666667 | M35: =IF(L35="-","-",IF(L35>=70,"A",IF(L35>=50,"C",IF(L35>=40,"P","F")))) -> F
A36: SOCIAL STUDIES | F36: =VLOOKUP(C8,'3rd Term'!B9:AN48,36,FALSE) -> 26 | G36: =VLOOKUP(C8,'3rd Term'!B9:AN48,37,FALSE) -> 45 | H36: =SUM(F36:G36) -> 71 | I36: =(VLOOKUP(C8,'2nd Term'!B9:AN48,36,FALSE))+(VLOOKUP(C8,'2nd Term'!B9:AN48,37,FALSE)) -> 39 | J36: =(VLOOKUP($C$8,'1st Term'!$B$9:$AN$48,36,FALSE))+(VLOOKUP($C$8,'1st Term'!$B$9:$AN$48,37,FALSE)) -> 31 | K36: =IF(SUM(H36:J36)=0,"-",SUM(H36:J36)) -> 141 | L36: =IFERROR(((H36)+(I36)+(J36))/((--(H36>0))+(--(I36>0))+(--(J36>0))),"-") -> 47 | M36: =IF(L36="-","-",IF(L36>=70,"A",IF(L36>=50,"C",IF(L36>=40,"P","F")))) -> P
A37: YORUBA LANGUAGE | F37: =VLOOKUP(C8,'3rd Term'!B9:AN48,38,FALSE) -> 25 | G37: =VLOOKUP(C8,'3rd Term'!B9:AN48,39,FALSE) -> 57 | H37: =SUM(F37:G37) -> 82 | I37: =(VLOOKUP(C8,'2nd Term'!B9:AN48,38,FALSE))+(VLOOKUP(C8,'2nd Term'!B9:AN48,39,FALSE)) -> 39 | J37: =(VLOOKUP($C$8,'1st Term'!$B$9:$AN$48,38,FALSE))+(VLOOKUP($C$8,'1st Term'!$B$9:$AN$48,39,FALSE)) -> 43 | K37: =IF(SUM(H37:J37)=0,"-",SUM(H37:J37)) -> 164 | L37: =IFERROR(((H37)+(I37)+(J37))/((--(H37>0))+(--(I37>0))+(--(J37>0))),"-") -> 54.666667 | M37: =IF(L37="-","-",IF(L37>=70,"A",IF(L37>=50,"C",IF(L37>=40,"P","F")))) -> C
G43: SIGNATURE & STAMP
A44: CLASS TEACHER'S REMARK:
A45: =VLOOKUP(C8,comments!B8:X47,7,0) -> He is sometimes playful in class and needs to concentrate more.
A47: PRINCIPAL'S COMMENT:
A48: =VLOOKUP(C8,comments!B8:X47,14,0) -> Poor result. Learn to devote time to private/personal studies. Promoted to the Next Class.
A50: KEYS TO GRADE:
...

Sheet sheet2
B1: EASYNETT INT'L COLLEGE OF TECH.
B3: 76, WILMER CRESCENT, OLODI-APAPA, LAGOS
B4: TEL: 07030903097, 08054260717
B5: REPORT CARD
K7: PASSPORT PHOTO
A8: Student Name: | C8: =('1st Term'!B10) -> ADEOLA PEDRO
A9: Class: | C9: =('1st Term'!B7) -> JSS 1A
A10: Session: | C10: =(comments!C4) -> 2025/2026
A11: Term: | C11: =(comments!B5) -> THIRD TERM | F11: Cum Average: | H11: =INDEX(comments!D8:D47,MATCH(sheet2!C8,comments!B8:B47,0)) -> 51.019608
A12: Next Term Begins: | C12: =(comments!E6) -> 20TH APRIL 2026 | F12: Position: | H12: =INDEX(comments!E8:E47,MATCH(sheet2!C8,comments!B8:B47,0)) -> 14th
A14: FREQUENCIES | D14: SCHOOL ATTENDANCE | I14: PSYCHOMOTOR | J14: PUNCTUALITY | M14: D
A15: No. of times School Opened: | D15: =(comments!C6) -> 110 | J15: NEATNESS | M15: C
A16: No. of times Present: | D16: =VLOOKUP(C8,comments!B8:C47,2,FALSE) -> 0 | J16: HONESTY | M16: C
A17: No. in Class: | D17: =(comments!D6) -> 22 | J17: CREATIVITY | M17: D
A18: SUBJECT | F18: Third Term CA | G18: Third Term Exam | H18: Third Term Total | I18: Second Term Score | J18: First Term Score | K18: Cum Total | L18: Cum Average | M18: GRADE
A19: AGRICULTURAL SCIENCE | F19: =VLOOKUP(C8,'3rd Term'!B9:AN48,2,FALSE) -> 21 | G19: =VLOOKUP(C8,'3rd Term'!B9:AN48,3,FALSE) -> 21 | H19: =SUM(F19:G19) -> 42 | I19: =(VLOOKUP(C8,'2nd Term'!B9:AN48,2,FALSE))+(VLOOKUP(C8,'2nd Term'!B9:AN48,3,FALSE)) -> 67 | J19: =(VLOOKUP($C$8,'1st Term'!$B$9:$AN$48,2,FALSE))+(VLOOKUP($C$8,'1st Term'!$B$9:$AN$48,3,FALSE)) -> 67 | K19: =IF(SUM(H19:J19)=0,"-",SUM(H19:J19)) -> 176 | L19: =IFERROR(((H19)+(I19)+(J19))/((--(H19>0))+(--(I19>0))+(--(J19>0))),"-") -> 58.666667 | M19: =IF(L19="-","-",IF(L19>=70,"A",IF(L19>=50,"C",IF(L19>=40,"P","F")))) -> C
A20: BASIC SCIENCE | F20: =VLOOKUP(C8,'3rd Term'!B9:AN48,4,FALSE) -> 20 | G20: =VLOOKUP(C8,'3rd Term'!B9:AN48,5,FALSE) -> 35 | H20: =SUM(F20:G20) -> 55 | I20: =(VLOOKUP(C8,'2nd Term'!B9:AN48,4,FALSE))+(VLOOKUP(C8,'2nd Term'!B9:AN48,5,FALSE)) -> 77 | J20: =(VLOOKUP($C$8,'1st Term'!$B$9:$AN$48,4,FALSE))+(VLOOKUP($C$8,'1st Term'!$B$9:$AN$48,5,FALSE)) -> 64 | K20: =IF(SUM(H20:J20)=0,"-",SUM(H20:J20)) -> 196 | L20: =IFERROR(((H20)+(I20)+(J20))/((--(H20>0))+(--(I20>0))+(--(J20>0))),"-") -> 65.333333 | M20: =IF(L20="-","-",IF(L20>=70,"A",IF(L20>=50,"C",IF(L20>=40,"P","F")))) -> C
A21: BASIC TECH | F21: =VLOOKUP(C8,'3rd Term'!B9:AN48,6,FALSE) -> 13 | G21: =VLOOKUP(C8,'3rd Term'!B9:AN48,7,FALSE) -> 34 | H21: =SUM(F21:G21) -> 47 | I21: =(VLOOKUP(C8,'2nd Term'!B9:AN48,6,FALSE))+(VLOOKUP(C8,'2nd Term'!B9:AN48,7,FALSE)) -> 54 | J21: =(VLOOKUP($C$8,'1st Term'!$B$9:$AN$48,6,FALSE))+(VLOOKUP($C$8,'1st Term'!$B$9:$AN$48,7,FALSE)) -> 42 | K21: =IF(SUM(H21:J21)=0,"-",SUM(H21:J21)) -> 143 | L21: =IFERROR(((H21)+(I21)+(J21))/((--(H21>0))+(--(I21>0))+(--(J21>0))),"-") -> 47.666667 | M21: =IF(L21="-","-",IF(L21>=70,"A",IF(L21>=50,"C",IF(L21>=40,"P","F")))) -> P
A22: BUSINESS STUDIES | F22: =VLOOKUP(C8,'3rd Term'!B9:AN48,8,FALSE) -> 25 | G22: =VLOOKUP(C8,'3rd Term'!B9:AN48,9,FALSE) -> 27 | H22: =SUM(F22:G22) -> 52 | I22: =(VLOOKUP(C8,'2nd Term'!B9:AN48,8,FALSE))+(VLOOKUP(C8,'2nd Term'!B9:AN48,9,FALSE)) -> 42 | J22: =(VLOOKUP($C$8,'1st Term'!$B$9:$AN$48,8,FALSE))+(VLOOKUP($C$8,'1st Term'!$B$9:$AN$48,9,FALSE)) -> 47 | K22: =IF(SUM(H22:J22)=0,"-",SUM(H22:J22)) -> 141 | L22: =IFERROR(((H22)+(I22)+(J22))/((--(H22>0))+(--(I22>0))+(--(J22>0))),"-") -> 47 | M22: =IF(L22="-","-",IF(L22>=70,"A",IF(L22>=50,"C",IF(L22>=40,"P","F")))) -> P
